Workbook
Name _001: #REF!
Name _001: #REF!
Name _001: #REF!
Name _001: #REF!
Name _001: #REF!
Name _152: #REF!
Name _152: #REF!
Name _152: #REF!
Name _152: #REF!
Name _152: #REF!
Name _152: #REF!
Name _152: #REF!
Name _152: #REF!
Name _152: #REF!
Name _152: #REF!
Name _152: #REF!
Name _152: #REF!
Name _152: #REF!
Name _152: #REF!
Name _152: #REF!
Name _152: #REF!
Name _152: #REF!
Name _153: #REF!
Name _153: #REF!
Name _153: #REF!
Name _153: #REF!
Name _153: #REF!
Name _153: #REF!
Name _153: #REF!
Name _153: #REF!
Name _153: #REF!
Name _153: #REF!
Name _153: #REF!
Name _153: #REF!
Name _153: #REF!
Name _153: #REF!
Name _154: #REF!
Name _154: #REF!
Name _154: #REF!
Name _154: #REF!
Name _154: #REF!
Name _1593: #REF!
Name _1593: #REF!
Name _1593: #REF!
Name _1593: #REF!
Name _1593: #REF!
Name _1593: #REF!
Name _1593: #REF!
Name _1593: #REF!
Name _1593: #REF!
Name _1593: #REF!
Name _17: #REF!
Name _17: #REF!
Name _17: #REF!
Name _17: #REF!
Name _17: #REF!
Name _17: #REF!
Name _17: #REF!
Name _17: #REF!
Name _17: #REF!

Sheet CDD - 08.02.2026-SHIPPED
H2: =NOW()-TRUNC(NOW()) -> 0.61871759 | I2: G Total | J2: =SUBTOTAL(9,J47,J5:J6,J9:J25,J50,J53:J57,J28,J33) -> 8849 | K2: =SUBTOTAL(9,K47,K5:K6,K9:K25,K50,K53:K57,K28) -> 9752 | L2: =SUBTOTAL(9,L47,L5:L6,L9:L25,L50,L53:L57,L28) -> 9724 | M2: =SUBTOTAL(9,M47,M5:M6,M9:M25,M50,M53:M57,M28) -> 28 | N2: =SUBTOTAL(9,N47,N5:N6,N9:N25,N50,N53:N57,N28) -> 9689 | O2: =SUBTOTAL(9,O47,O5:O6,O9:O25,O50,O53:O57,O28) -> 6 | P2: 8603 | Q2: 461
E3: SEA - FOB - CHENNAI | F3: TRUCKOUT ON - 29.01.2025 | U3: =TODAY() -> 46120 | AB3: MAIL
B4: F Line | C4: PLANT CODE | D4: LINE NO | E4: CON | F4: DESTINATION | G4: PO NO | H4: COLOR | I4: MATERIAL NO | J4: QTY | K4: CUT QTY | L4: Send to Wash / Dye | M4: Balance to Send | N4: Wash / Dye Received | O4: Balance to receive | P4: PACK/SHIP QTY | Q4: CTNS | R4: STATUS | S4: GROSS Weight | T4: Net Weight | U4: FI to be done by | V4: ASN | W4: WEIGHT | X4: WFX | Y4: OCR | Z4: BOOKING NO | AA4: DO
C5: V992 | D5: 10 | E5: PRLS/25/12440 | F5: HONG KONG | G5: 4702056493 | H5: SKY LAVENDER | I5: 710966294501 | J5: 42 | K5: 728 | L5: 725 | M5: 3 | N5: 723 | O5: 2 | P5: 41 | Q5: 3 | R5: SHIPPED | S5: 17.10 | T5: 13.26 | V5: SENT | W5: DONE | X5: DONE | Y5: DONE | Z5: IBKG0000228110 | AA5: SMAAS089118 - AS SHIPPING CFS - CHENNAI | AB5: SENT
C6: V992 | D6: 10 | E6: PRLS/25/12439 | F6: HONG KONG | G6: 4702056491 | H6: SKY LAVENDER | I6: 710966293023 | J6: 115 | K6: 115 | L6: 115 | M6: 0 | N6: 115 | O6: 0 | P6: 115 | Q6: 6 | R6: SHIPPED | S6: 35.36 | T6: 27.68 | V6: SENT | W6: DONE | X6: DONE | Y6: DONE | AB6: SENT
F7: TOTAL | J7: =SUM(J5:J6) -> 157 | K7: =SUM(K5:K6) -> 843 | L7: =SUM(L5:L6) -> 840 | M7: =SUM(M5:M6) -> 3 | N7: =SUM(N5:N6) -> 838 | O7: =SUM(O5:O6) -> 2 | P7: =SUM(P5:P6) -> 156 | Q7: =SUM(Q5:Q6) -> 9
C9: CA10 | D9: 30 | E9: PRLS/25/12737 | F9: ITALY | G9: 4702068711 | H9: 6671I POWDER PURPLE/WHITE | I9: 710B22588003 | J9: 780 | K9: 825 | L9: 819 | M9: 6 | N9: 819 | O9: 0 | P9: 797 | Q9: 47 | R9: SHIPPED | S9: 297.33 | T9: 237.67 | V9: SENT | W9: DONE | X9: DONE | Y9: DONE | Z9: IBKG0000228157 | AA9: SMAAS089125 AS SHIPPING CFS - CHENNAI | AB9: SENT
C10: CA10 | D10: 10 | E10: PRLS/25/12739 | F10: ITALY | G10: 4702068712 | H10: 6555H COASTAL BEIGE/WHITE | I10: 710B22589001 | J10: 600 | K10: 646 | L10: 641 | M10: 5 | N10: 637 | O10: 4 | P10: 613 | Q10: 36 | R10: SHIPPED | S10: 229.38 | T10: 183.02 | V10: SENT | W10: DONE | X10: DONE | Y10: DONE
C11: CA10 | D11: 20 | E11: PRLS/25/12741 | F11: ITALY | G11: 4702068712 | H11: 6555B CABANA BLUE/WHITE | I11: 710B22589002 | J11: 1000 | K11: 1080 | L11: 1077 | M11: 3 | N11: 1077 | O11: 0 | P11: 1026 | Q11: 59 | R11: SHIPPED | S11: 395.39 | T11: 319.87 | V11: SENT | W11: DONE | X11: DONE | Y11: DONE | AB11: SENT
C12: CA10 | D12: 10 | E12: PRLS/25/12741 | F12: ITALY | G12: 4702083750 | H12: 6555B CABANA BLUE/WHITE | I12: 710B22589002 | J12: 44 | K12: 44 | L12: 44 | M12: 0 | N12: 44 | O12: 0 | P12: 44 | Q12: 3 | R12: SHIPPED | S12: 17.363 | T12: 13.52 | V12: SENT | W12: DONE | X12: DONE | Y12: DONE | AB12: SENT
C13: CA10 | D13: 20 | E13: PRLS/25/12741 | F13: ITALY | G13: 4702083767 | H13: 6555B CABANA BLUE/WHITE | I13: 710B22589002 | J13: 47 | K13: 47 | L13: 47 | M13: 0 | N13: 47 | O13: 0 | P13: 47 | Q13: 3 | R13: SHIPPED | S13: 15.84 | T13: 14.56 | V13: SENT | W13: DONE | X13: DONE | Y13: DONE | AB13: SENT
C14: CA10 | D14: 10 | E14: PRLS/25/12739 | F14: ITALY | G14: 4702083767 | H14: 6555H COASTAL BEIGE/WHITE | I14: 710B22589001 | J14: 17 | K14: 17 | L14: 17 | M14: 0 | N14: 17 | O14: 0 | P14: 17 | Q14: 1 | R14: SHIPPED | S14: 8.91 | T14: 5.07 | V14: SENT | W14: DONE | X14: DONE | Y14: DONE | AB14: SENT
C15: CA10 | D15: 20 | E15: PRLS/25/12741 | F15: ITALY | G15: 4702083793 | H15: 6555B CABANA BLUE/WHITE | I15: 710B22589002 | J15: 48 | K15: 48 | L15: 48 | M15: 0 | N15: 48 | O15: 0 | P15: 48 | Q15: 3 | R15: SHIPPED | S15: 18.70 | T15: 14.86 | V15: SENT | W15: DONE | X15: DONE | Y15: DONE | AB15: SENT
C16: CA10 | D16: 10 | E16: PRLS/25/12739 | F16: ITALY | G16: 4702083793 | H16: 6555H COASTAL BEIGE/WHITE | I16: 710B22589001 | J16: 29 | K16: 29 | L16: 29 | M16: 0 | N16: l | O16: 0 | P16: 29 | Q16: 3 | R16: SHIPPED | S16: 12.37 | T16: 8.53 | V16: SENT | W16: DONE | X16: DONE | Y16: DONE | AB16: SENT
C17: CA10 | D17: 20 | E17: PRLS/25/12741 | F17: ITALY | G17: 4702083827 | H17: 6555B CABANA BLUE/WHITE | I17: 710B22589002 | J17: 48 | K17: 48 | L17: 48 | M17: 0 | N17: 48 | O17: 0 | P17: 48 | Q17: 3 | R17: SHIPPED | S17: 18.70 | T17: 14.86 | V17: SENT | W17: DONE | X17: DONE | Y17: DONE | AB17: SENT
C18: CA10 | D18: 10 | E18: PRLS/25/12739 | F18: ITALY | G18: 4702083827 | H18: 6555H COASTAL BEIGE/WHITE | I18: 710B22589001 | J18: 29 | K18: 29 | L18: 29 | M18: 0 | N18: 29 | O18: 0 | P18: 29 | Q18: 3 | R18: SHIPPED | S18: 12.48 | T18: 8.64 | V18: SENT | W18: DONE | X18: DONE | Y18: DONE | AB18: SENT
C19: CA10 | D19: 20 | E19: PRLS/25/12741 | F19: ITALY | G19: 4702083856 | H19: 6555B CABANA BLUE/WHITE | I19: 710B22589002 | J19: 47 | K19: 47 | L19: 47 | M19: 0 | N19: 47 | O19: 0 | P19: 47 | Q19: 3 | R19: SHIPPED | S19: 18.40 | T19: 14.56 | V19: SENT | W19: DONE | X19: DONE | Y19: DONE | AB19: SENT
C20: CA10 | D20: 10 | E20: PRLS/25/12739 | F20: ITALY | G20: 4702083856 | H20: 6555H COASTAL BEIGE/WHITE | I20: 710B22589001 | J20: 25 | K20: 25 | L20: 25 | M20: 0 | N20: 25 | O20: 0 | P20: 25 | Q20: 2 | R20: SHIPPED | S20: 10.04 | T20: 7.48 | V20: SENT | W20: DONE | X20: DONE | Y20: DONE | AB20: SENT
C21: CA10 | D21: 10 | E21: PRLS/25/12741 | F21: ITALY | G21: 4702083881 | H21: 6555B CABANA BLUE/WHITE | I21: 710B22589002 | J21: 46 | K21: 46 | L21: 46 | M21: 0 | N21: 46 | O21: 0 | P21: 46 | Q21: 3 | R21: SHIPPED | S21: 18.07 | T21: 14.23 | V21: SENT | W21: DONE | X21: DONE | Y21: DONE | AB21: SENT
C22: CA10 | D22: 10 | E22: PRLS/25/12741 | F22: ITALY | G22: 4702083891 | H22: 6555B CABANA BLUE/WHITE | I22: 710B22589002 | J22: 5 | K22: 5 | L22: 5 | M22: 0 | N22: 5 | O22: 0 | P22: 5 | Q22: 1 | R22: SHIPPED | S22: 2.80 | T22: 1.52 | V22: SENT | W22: DONE | X22: DONE | Y22: DONE | AB22: SENT
C23: CA10 | D23: 10 | E23: PRLS/25/12741 | F23: ITALY | G23: 4702083899 | H23: 6555B CABANA BLUE/WHITE | I23: 710B22589002 | J23: 36 | K23: 36 | L23: 36 | M23: 0 | N23: 36 | O23: 0 | P23: 36 | Q23: 2 | R23: SHIPPED | S23: 13.65 | T23: 11.09 | V23: SENT | W23: DONE | X23: DONE | Y23: DONE | AB23: SENT
C24: CA10 | D24: 10 | E24: PRLS/25/12741 | F24: ITALY | G24: 4702083906 | H24: 6555B CABANA BLUE/WHITE | I24: 710B22589002 | J24: 33 | K24: 33 | L24: 33 | M24: 0 | N24: 33 | O24: 0 | P24: 33 | Q24: 3 | R24: SHIPPED | S24: 14.05 | T24: 10.21 | V24: SENT | W24: DONE | X24: DONE | Y24: DONE | AB24: SENT
C25: CA10 | D25: 10 | E25: PRLS/25/12741 | F25: ITALY | G25: 4702083916 | H25: 6555B CABANA BLUE/WHITE | I25: 710B22589002 | J25: 46 | K25: 46 | L25: 46 | M25: 0 | N25: 46 | O25: 0 | P25: 46 | Q25: 3 | R25: SHIPPED | S25: 18.07 | T25: 14.23 | V25: SENT | W25: DONE | X25: DONE | Y25: DONE | AB25: SENT
F26: TOTAL | J26: =SUM(J9:J25) -> 2880 | K26: =SUM(K9:K25) -> 3051 | L26: =SUM(L9:L25) -> 3037 | M26: =SUM(M9:M25) -> 14 | N26: =SUM(N9:N25) -> 3004 | O26: =SUM(O9:O25) -> 4 | P26: =SUM(P9:P25) -> 2936 | Q26: =SUM(Q9:Q25) -> 178
C28: NW00 | D28: 10 | E28: PRLS/25/12448 | F28: US | G28: 4702059563 | H28: SKY LAVENDER | I28: 711966293501 | J28: 678 | K28: 677 | L28: 676 | M28: 1 | N28: 676 | O28: 0 | P28: 653 | Q28: 38 | R28: SHIPPED | S28: 281.83 | T28: 233.19 | V28: SENT | W28: DONE | X28: DONE | Y28: DONE | Z28: IBKG0000228123 | AA28: SMAAS089119 AS SHIPPING CFS - CHENNAI | AB28: SENT
F29: TOTAL | J29: =SUM(J28) -> 678 | K29: =SUM(K28) -> 677 | L29: =SUM(L28) -> 676 | M29: =SUM(M28) -> 1 | N29: =SUM(N28) -> 676 | O29: =SUM(O28) -> 0 | P29: =SUM(P28) -> 653 | Q29: =SUM(Q28) -> 38
E31: AIR - FCA - BANGALORE | F31: TRUCKOUT ON - 29.01.2025 | I31: CDD-08-02-2026
B32: F Line | C32: PLANT CODE | D32: LINE NO | E32: CON | F32: DESTINATION | G32: PO NO | H32: COLOR | I32: MATERIAL NO | J32: QTY | K32: CUT QTY | L32: Send to Wash / Dye | M32: Balance to Send | N32: Wash / Dye Received | O32: Balance to receive | P32: PACK/SHIP QTY | Q32: CTNS | R32: STATUS | S32: STATUS-2 | T32: FI to be done by | V32: ASN | W32: WEIGHT | X32: WFX | Y32: OCR | Z32: BOOKING NO | AA32: DO
C33: V994 | D33: 20 | E33: PRLS/25/12439 | F33: RL-Mexico | G33: 4702064965 | H33: SKY LAVENDER | I33: 710966293023 | J33: 836 | P33: 844 | Q33: 40 | R33: shipped | V33: SENT | W33: DONE | X33: DONE | Y33: DONE | Z33: IBKG0000233639
F34: TOTAL | J34: =SUM(J33:J33) -> 836 | K34: =SUM(K33:K33) -> 0 | L34: =SUM(L33:L33) -> 0 | M34: =SUM(M33:M33) -> 0 | N34: =SUM(N33:N33) -> 0 | O34: =SUM(O33:O33) -> 0 | P34: =SUM(P33:P33) -> 844 | Q34: =SUM(Q33:Q33) -> 40
B36: GRAND TOTAL | J36: =J48+J7+J26+J51+J29+J34 -> 8597 | K36: =K48+K7+K26+K51+K29+K34 -> 9502 | L36: =L48+L7+L26+L51+L29+L34 -> 9474 | M36: =M48+M7+M26+M51+M29+M34 -> 28 | N36: =N48+N7+N26+N51+N29+N34 -> 9439 | O36: =O48+O7+O26+O51+O29+O34 -> 6 | P36: =P48+P7+P26+P51+P29+P34 -> 8603 | Q36: =Q48+Q7+Q26+Q51+Q29+Q34 -> 461
E38: AIR - FCA - BANGALORE | F38: TRUCKOUT ON - 13.01.2025 | I38: CDD-01-02-2026
B39: F Line | C39: PLANT CODE | D39: LINE NO | E39: CON | F39: DESTINATION | G39: PO NO | H39: COLOR | I39: MATERIAL NO | J39: QTY | K39: CUT QTY | L39: Send to Wash / Dye | M39: Balance to Send | N39: Wash / Dye Received | O39: Balance to receive | P39: PACK/SHIP QTY | Q39: CTNS | R39: STATUS | S39: STATUS-2 | T39: FI to be done by | V39: ASN | W39: WEIGHT | X39: WFX | Y39: OCR | Z39: BOOKING NO | AA39: DO
C40: CA10 | D40: 20 | E40: PRLS/25/12440 | F40: ITALY | G40: 4702056492 | H40: SKY LAVENDER | I40: 710966294501 | J40: 658 | P40: 666 | Q40: 39 | R40: shipped | V40: SENT | W40: DONE | X40: DONE | Y40: DONE | Z40: IBKG0000224369
F41: TOTAL | J41: =SUM(J40:J40) -> 658 | K41: =SUM(K40:K40) -> 0 | L41: =SUM(L40:L40) -> 0 | M41: =SUM(M40:M40) -> 0 | N41: =SUM(N40:N40) -> 0 | O41: =SUM(O40:O40) -> 0 | P41: =SUM(P40:P40) -> 666 | Q41: =SUM(Q40:Q40) -> 39
E43: AIR - FCA - BANGALORE | F43: TRUCKOUT ON - 13.01.2025 | I43: CDD-01-02-2026
B44: F Line | C44: PLANT CODE | D44: LINE NO | E44: CON | F44: DESTINATION | G44: PO NO | H44: COLOR | I44: MATERIAL NO | J44: QTY | K44: CUT QTY | L44: Send to Wash / Dye | M44: Balance to Send | N44: Wash / Dye Received | O44: Balance to receive | P44: PACK/SHIP QTY | Q44: CTNS | R44: STATUS | S44: STATUS-2 | T44: FI to be done by | V44: ASN | W44: WEIGHT | X44: WFX | Y44: OCR | Z44: BOOKING NO | AA44: INV-NO
B45: RRL | C45: V994 | D45: 20 | E45: PRLS/25/10826 | F45: JAPAN | G45: 4701983749 | H45: BLUE MULTI | I45: 782P05347001 | J45: 56 | P45: 56 | Q45: 2 | R45: shipped | V45: sent | W45: DONE | X45: DONE | Y45: DONE | Z45: IBKG0000234269-FEDEX | AA45: LCPEXP2526-2950
F46: TOTAL | J46: =SUM(J44:J45) -> 56 | K46: =SUM(K44:K45) -> 0 | L46: =SUM(L44:L45) -> 0 | M46: =SUM(M44:M45) -> 0 | N46: =SUM(N44:N45) -> 0 | O46: =SUM(O44:O45) -> 0 | P46: =SUM(P44:P45) -> 56 | Q46: =SUM(Q44:Q45) -> 2
C47: TO17 | D47: 10 | E47: PRLS/25/12448 | F47: CANADA | G47: 4702059564 | H47: SKY LAVENDER | I47: 711966293501 | J47: 302 | K47: 302 | L47: 302 | M47: 0 | N47: 302 | O47: 0 | P47: 302 | Q47: 18 | R47: SHIPPED | S47: 126.32 | T47: 103.28 | V47: DONE | W47: DONE | X47: DONE | Y47: DONE | Z47: IBKG0000228102 | AA47: JENNA MUMBAI CFS | AB47: SENT
...

Sheet CDD - 01.02.2026- SHIPPED
H2: =NOW()-TRUNC(NOW()) -> 0.61871759 | I2: G Total | J2: =SUBTOTAL(9,J7,J18:J21,J45:J47,J50:O58,J24:J32,J35:J38,J41,J6) -> 17832 | K2: =SUBTOTAL(9,K7,K18:K21,K45:K47,K50:P58,K24:K32,K35:K38,K41,K6) -> 8270 | L2: =SUBTOTAL(9,L7,L18:L21,L45:L47,L50:Q58,L24:L32,L35:L38,L41,L6) -> 6662 | M2: =SUBTOTAL(9,M7,M18:M21,M45:M47,M50:R58,M24:M32,M35:M38,M41,M6) -> 6855 | N2: =SUBTOTAL(9,N7,N18:N21,N45:N47,N50:S58,N24:N32,N35:N38,N41,N6) -> 5934 | O2: =SUBTOTAL(9,O7,O18:O21,O45:O47,O50:T58,O24:O32,O35:O38,O41,O6) -> 5704 | P2: =SUBTOTAL(9,P7,P18:P21,P45:P47,P50:U58,P24:P32,P35:P38,P41,P6) -> 17878 | Q2: =SUBTOTAL(9,Q7,Q18:Q21,Q45:Q47,Q50:V58,Q24:Q32,Q35:Q38,Q41,Q6) -> 999 | R2: =SUBTOTAL(9,#REF!,R45:R47,R52:R53,R57,R24,R3:R38) -> #REF!
E4: AIR - FCA - BANGALORE | F4: TRUCKOUT ON - 13.01.2025 | H4: TRUCKOUT ON - 13.01.2025
B5: F Line | C5: PLANT CODE | D5: LINE NO | E5: CON | F5: DESTINATION | G5: PO NO | H5: COLOR | I5: MATERIAL NO | J5: QTY | K5: CUT QTY | L5: Send to Wash / Dye | M5: Balance to Send | N5: Wash / Dye Received | O5: Balance to receive | P5: PACK/SHIP QTY | Q5: CTNS | R5: STATUS | S5: STATUS-2 | T5: FI to be done by | U5: ASN | V5: WEIGHT | W5: WFX | X5: OCR | Y5: BOOKING NO | Z5: DO
C6: V994 | D6: 20 | E6: PRLS/25/10826 | F6: JAPAN | G6: 4701983749 | H6: BLUE MULTI | I6: 782P05347001 | J6: 56
C7: CA10 | D7: 20 | E7: PRLS/25/12440 | F7: ITALY | G7: 4702056492 | H7: SKY LAVENDER | I7: 710966294501 | J7: 658 | P7: 666 | Q7: 39 | R7: Ready | U7: DONE | V7: DONE | W7: DONE | X7: DONE | Y7: IBKG0000224369 | Z7: SMAAS088997
F8: TOTAL | J8: =SUM(J6:J7) -> 714 | K8: =SUM(K6:K7) -> 0 | L8: =SUM(L6:L7) -> 0 | M8: =SUM(M6:M7) -> 0 | N8: =SUM(N6:N7) -> 0 | O8: =SUM(O6:O7) -> 0 | P8: =SUM(P6:P7) -> 666 | Q8: =SUM(Q6:Q7) -> 39
B9: GRAND TOTAL | J9: =+J8+J59+J48 -> 7531 | K9: =+K8+K59+K48 -> 2190 | L9: =+L8+L59+L48 -> 1686 | M9: =+M8+M59+M48 -> 0 | N9: =+N8+N59+N48 -> 958 | O9: =+O8+O59+O48 -> 728 | P9: =+P8+P59+P48 -> 7553 | Q9: =+Q8+Q59+Q48 -> 436
E16: SEA - FOB - CHENNAI | F16: TRUCKOUT ON - 13.01.2025 | T16: =TODAY() -> 46120
B17: F Line | C17: PLANT CODE | D17: LINE NO | E17: CON | F17: DESTINATION | G17: PO NO | H17: COLOR | I17: MATERIAL NO | J17: QTY | K17: CUT QTY | L17: Send to Wash / Dye | M17: Balance to Send | N17: Wash / Dye Received | O17: Balance to receive | P17: PACK/SHIP QTY | Q17: CTNS | R17: STATUS | S17: STATUS-2 | T17: FI to be done by | U17: ASN | V17: WEIGHT | W17: WFX | X17: OCR | Y17: BOOKING NO | Z17: DO
C18: CA20 | D18: 10 | E18: PRLS/25/12644 | F18: ITALY | G18: 4702054149 | H18: HARBOR ISLAND BLUE | I18: 710P07023004 | J18: 836 | P18: 836 | Q18: 38 | R18: Shipped | U18: SENT | V18: DONE | W18: DONE | X18: DONE | Y18: IBKG0000224531 | Z18: SMAAS089008 -AS SHIPPING
C19: CA20 | D19: 10 | E19: PRLS/25/12644 | F19: ITALY | G19: 4702054150 | H19: HARBOR ISLAND BLUE | I19: 710P07023004 | J19: 374 | P19: 374 | Q19: 17 | R19: Shipped | U19: SENT | V19: DONE | W19: DONE | X19: DONE
C20: CA20 | D20: 20 | E20: PRLS/25/12327 | F20: ITALY | G20: 4702054301 | H20: POLO BLACK | I20: 710966294019 | J20: 638 | P20: 594 | Q20: 27 | R20: Shipped | U20: SENT | V20: DONE | W20: DONE | X20: DONE
C21: CA20 | D21: 20 | E21: PRLS/25/12327 | F21: ITALY | G21: 4702054302 | H21: POLO BLACK | I21: 710966294019 | J21: 308 | P21: 308 | Q21: 14 | R21: Shipped | U21: SENT | V21: DONE | W21: DONE | X21: DONE
F22: TOTAL | J22: =SUM(J18:J21) -> 2156 | K22: =SUM(K18:K21) -> 0 | L22: =SUM(L18:L21) -> 0 | M22: =SUM(M18:M21) -> 0 | N22: =SUM(N18:N21) -> 0 | O22: =SUM(O18:O21) -> 0 | P22: =SUM(P18:P21) -> 2112 | Q22: =SUM(Q18:Q21) -> 96
C24: V992 | D24: 10 | E24: PRLS/25/12339 | F24: HONG KONG | G24: 4702049219 | H24: 5137B PINK/WHITE | I24: 710B22228002 | J24: 720 | P24: 541 | Q24: 33 | R24: Shipped | U24: SENT | V24: DONE | W24: DONE | X24: DONE | Y24: IBKG0000226902 | Z24: SMAAS089080 -AS SHIPPING
C25: V992 | D25: 20 | E25: PRLS/25/12225 | F25: HONG KONG | G25: 4702049219 | H25: 5137F CHOCOLATE MOUSSE/WHITE | I25: 710B22228003 | J25: 225 | P25: 225 | Q25: 13 | R25: Shipped | U25: SENT | V25: DONE | W25: DONE | X25: DONE
C26: V992 | D26: 10 | E26: PRLS/25/12339 | F26: HONG KONG | G26: 4702049220 | H26: 5137B PINK/WHITE | I26: 710B22228002 | J26: 690 | P26: 538 | Q26: 32 | R26: Shipped | U26: SENT | V26: DONE | W26: DONE | X26: DONE
C27: V992 | D27: 20 | E27: PRLS/25/12225 | F27: HONG KONG | G27: 4702049220 | H27: 5137F CHOCOLATE MOUSSE/WHITE | I27: 710B22228003 | J27: 687 | P27: 704 | Q27: 41 | R27: Shipped | U27: SENT | V27: DONE | W27: DONE | X27: DONE
C28: V992 | D28: 20 | E28: PRLS/25/12225 | F28: HONG KONG | G28: 4702049221 | H28: 5137F CHOCOLATE MOUSSE/WHITE | I28: 710B22228003 | J28: 40 | P28: 40 | Q28: 3 | R28: Shipped | U28: SENT | V28: DONE | W28: DONE | X28: DONE
C29: V992 | D29: 10 | E29: PRLS/25/12339 | F29: HONG KONG | G29: 4702049221 | H29: 5137B PINK/WHITE | I29: 710B22228002 | J29: 40 | P29: 40 | Q29: 3 | R29: Shipped | U29: SENT | V29: DONE | W29: DONE | X29: DONE
C30: V992 | D30: 10 | E30: PRLS/25/12221 | F30: HONG KONG | G30: 4702053668 | H30: BAYSIDE GREEN | I30: 710967669004 | J30: 410 | P30: 419 | Q30: 26 | R30: Shipped | U30: SENT | V30: DONE | W30: DONE | X30: DONE
C31: V992 | D31: 10 | E31: PRLS/25/12221 | F31: HONG KONG | G31: 4702053669 | H31: BAYSIDE GREEN | I31: 710967669004 | J31: 861 | P31: 882 | Q31: 51 | R31: Shipped | U31: SENT | V31: DONE | W31: DONE | X31: DONE
C32: V992 | D32: 10 | E32: PRLS/25/12221 | F32: HONG KONG | G32: 4702053670 | H32: BAYSIDE GREEN | I32: 710967669004 | J32: 32 | P32: 32 | Q32: 3 | R32: Shipped | U32: SENT | V32: DONE | W32: DONE | X32: DONE
F33: TOTAL | J33: =SUM(J24:J32) -> 3705 | K33: =SUM(K24:K32) -> 0 | L33: =SUM(L24:L32) -> 0 | M33: =SUM(M24:M32) -> 0 | N33: =SUM(N24:N32) -> 0 | O33: =SUM(O24:O32) -> 0 | P33: =SUM(P24:P32) -> 3421 | Q33: =SUM(Q24:Q32) -> 205
C35: V993 | D35: 10 | E35: PRLS/25/12223 | F35: KOREA | G35: 4702049212 | H35: 594C BLUE/WHITE | I35: 710B16388001 | J35: 1680 | P35: 1728 | Q35: 98 | R35: Shipped | U35: SENT | V35: DONE | W35: DONE | X35: DONE | Y35: IBKG0000224594 | Z35: SMAAS089012 -AS SHIPPING
C36: V993 | D36: 20 | E36: PRLS/25/12225 | F36: KOREA | G36: 4702049222 | H36: 5137F CHOCOLATE MOUSSE/WHITE | I36: 710B22228003 | J36: 640 | P36: 656 | Q36: 38 | R36: Shipped | U36: SENT | V36: DONE | W36: DONE | X36: DONE
C37: V993 | D37: 10 | E37: PRLS/25/12339 | F37: KOREA | G37: 4702049222 | H37: 5137B PINK/WHITE | I37: 710B22228002 | J37: 370 | P37: 378 | Q37: 22 | R37: Shipped | U37: SENT | V37: DONE | W37: DONE | X37: DONE
C38: V993 | D38: 10 | E38: PRLS/25/12221 | F38: KOREA | G38: 4702053671 | H38: BAYSIDE GREEN | I38: 710967669004 | J38: 410 | P38: 419 | Q38: 25 | R38: Shipped | U38: SENT | V38: DONE | W38: DONE | X38: DONE
F39: TOTAL | J39: =SUM(J35:J38) -> 3100 | K39: =SUM(K35:K38) -> 0 | L39: =SUM(L35:L38) -> 0 | M39: =SUM(M35:M38) -> 0 | N39: =SUM(N35:N38) -> 0 | O39: =SUM(O35:O38) -> 0 | P39: =SUM(P35:P38) -> 3181 | Q39: =SUM(Q35:Q38) -> 183
C41: V993 | D41: 10 | E41: PRLS/25/13183 | F41: KOREA | G41: 4702053666 | H41: COOPER BROWN | I41: 710967632004 | J41: 1340 | K41: 1375 | M41: 1879 | P41: 1340 | Q41: 79 | R41: Shipped | U41: SENT | V41: DONE | W41: DONE | X41: DONE | Y41: IBKG0000224595 | Z41: SMAAS089013 -AS SHIPPING
F42: TOTAL | J42: =SUM(J41) -> 1340 | K42: =SUM(K41) -> 1375 | L42: =SUM(L41) -> 0 | M42: =SUM(M41) -> 1879 | N42: =SUM(N41) -> 0 | O42: =SUM(O41) -> 0 | P42: =SUM(P41) -> 1340 | Q42: =SUM(Q41) -> 79
B44: F Line | C44: PLANT CODE | D44: LINE NO | E44: CON | F44: DESTINATION | G44: PO NO | H44: COLOR | I44: MATERIAL NO | J44: QTY | K44: CUT QTY | L44: Send to Wash / Dye | M44: Balance to Send | N44: Wash / Dye Received | O44: Balance to receive | P44: PACK/SHIP QTY | Q44: CTNS | R44: STATUS | S44: STATUS-2 | T44: FI to be done by | U44: ASN | V44: WEIGHT | W44: WFX | X44: OCR | Y44: BOOKING NO | Z44: DO
C45: V992 | D45: 10 | E45: PRLS/25/13183 | F45: HONG KONG | G45: 4702053663 | H45: COOPER BROWN | I45: 710967632004 | J45: 1070 | K45: 1101 | L45: 1101 | N45: 373 | O45: 728 | P45: 1074 | Q45: 61 | R45: Shipped | U45: DONE | V45: DONE | W45: DONE | X45: DONE | Y45: IBKG0000224552 | Z45: SMAAS089008 -AS SHIPPING
C46: V992 | D46: 10 | E46: PRLS/25/13183 | F46: HONG KONG | G46: 4702053664 | H46: COOPER BROWN | I46: 710967632004 | J46: 1068 | K46: 1089 | L46: 585 | N46: 585 | P46: 1068 | Q46: 62 | R46: Shipped | U46: DONE | V46: DONE | W46: DONE | X46: DONE
C47: V992 | D47: 10 | E47: PRLS/25/12210 | F47: HONG KONG | G47: 4702053665 | H47: COOPER BROWN | I47: 710967632004 | J47: 40 | P47: 40 | Q47: 3 | R47: Shipped | U47: DONE | V47: DONE | W47: DONE | X47: DONE
F48: TOTAL | J48: =SUM(J45:J47) -> 2178 | K48: =SUM(K45:K47) -> 2190 | L48: =SUM(L45:L47) -> 1686 | M48: =SUM(M45:M47) -> 0 | N48: =SUM(N45:N47) -> 958 | O48: =SUM(O45:O47) -> 728 | P48: =SUM(P45:P47) -> 2182 | Q48: =SUM(Q45:Q47) -> 126
C50: V992 | D50: 10 | E50: PRLS/25/12142 | F50: HONG KONG | G50: 4702043049 | H50: 7116B GREEN BLUE WHITE | I50: 710B16705001 | J50: 35 | P50: 35 | Q50: 3 | R50: Shipped | U50: DONE | V50: DONE | W50: DONE | X50: DONE | Y50: IBKG0000224575 | Z50: SMAAS089011 -AS SHIPPING
C51: V992 | D51: 10 | E51: PRLS/25/12442 | F51: HONG KONG | G51: 4702056497 | H51: AUSTIN BLUE | I51: 710968912501 | J51: 476 | P51: 479 | Q51: 23 | R51: Shipped | U51: DONE | V51: DONE | W51: DONE | X51: DONE
C52: V992 | D52: 20 | E52: PRLS/25/12441 | F52: HONG KONG | G52: 4702056493 | H52: AUSTIN BLUE | I52: 710966294509 | J52: 429 | P52: 401 | Q52: 24 | R52: Shipped | U52: DONE | V52: DONE | W52: DONE | X52: DONE
C53: V992 | D53: 30 | E53: PRLS/25/12141 | F53: HONG KONG | G53: 4702043043 | H53: 7188E COASTAL BEIGE WHITE | I53: 710B15594006 | J53: 477 | P53: 488 | Q53: 28 | R53: Shipped | U53: DONE | V53: DONE | W53: DONE | X53: DONE
...

Sheet CDD -26-01-2026 -SHIPPED
H2: =NOW()-TRUNC(NOW()) -> 0.61871759 | I2: G Total | J2: =SUBTOTAL(9,J5:J7,J11:J15,J19:J20,J24,J28,J32:J41,J46:J48) -> 12792 | K2: =SUBTOTAL(9,K5:K7,K11:K15,K19:K20,K24,K28,K32:K41) -> 21395 | L2: =SUBTOTAL(9,L5:L7,L11:L15,L19:L20,L24,L28,L32:L41) -> 18382 | M2: =SUBTOTAL(9,M5:M7,M11:M15,M19:M20,M24,M28,M32:M41) -> 3013 | N2: =SUBTOTAL(9,N5:N7,N11:N15,N19:N20,N24,N28,N32:N41) -> 18382 | O2: =SUBTOTAL(9,O5:O7,O11:O15,O19:O20,O24,O28,O32:O41) -> 0 | P2: =SUBTOTAL(9,P5:P7,P11:P15,P19:P20,P24,P28,P32:P41,P46:P48) -> 12975 | Q2: =SUBTOTAL(9,Q5:Q7,Q11:Q15,Q19:Q20,Q24,Q28,Q32:Q41,Q46:Q48) -> 954 | R2: =SUBTOTAL(9,R5:R7,R11:R15,R19:R20,R24,R28,R32:R41) -> 0
E3: SEA - FOB - CHENNAI | F3: TRUCKOUT ON - 13.01.2025 | T3: =TODAY() -> 46120
B4: F Line | C4: PLANT CODE | D4: LINE NO | E4: CON | F4: DESTINATION | G4: PO NO | H4: COLOR | I4: MATERIAL NO | J4: QTY | K4: CUT QTY | L4: Send to Wash / Dye | M4: Balance to Send | N4: Wash / Dye Received | O4: Balance to receive | P4: PACK/SHIP QTY | Q4: CTNS | R4: STATUS | S4: STATUS-2 | T4: FI to be done by | U4: ASN | V4: WEIGHT | W4: WFX | X4: OCR | Y4: BOOKING NO | Z4: DRAFT
B5: L -5 | C5: CA10 | D5: 10 | E5: PRLS/25/12444 | F5: ITALY | G5: 4702056498 | H5: AUSTIN BLUE | I5: 710968915504 | J5: 1000 | K5: 1036 | L5: 0 | M5: 1036 | N5: 0 | O5: 0 | P5: 1015 | Q5: 59 | R5: Ready | S5: Ready by - 17-01-2026 | U5: SENT | V5: SENT | W5: SENT | X5: SENT | Y5: IBKG0000220557
B6: L -5 | C6: CA10 | D6: 10 | E6: PRLS/25/12446 | F6: ITALY | G6: 4702056499 | H6: AUSTIN BLUE | I6: 711966292505 | J6: 400 | K6: 416 | L6: 413 | M6: 3 | N6: 413 | O6: 0 | P6: 400 | Q6: 28 | R6: Ready | S6: Ready By - 13-01-2026 | U6: SENT | V6: SENT | W6: SENT | X6: SENT
B7: L -8 | C7: CA10 | D7: 30 | E7: PRLS/25/12441 | F7: ITALY | G7: 4702056492 | H7: AUSTIN BLUE | I7: 710966294509 | J7: 2230 | K7: 2779 | L7: 2779 | M7: 0 | N7: 2779 | O7: 0 | P7: 2292 | Q7: 133 | R7: Ready | S7: Ready By - 19-01-2026 | U7: SENT | V7: SENT | W7: SENT | X7: SENT | Z7: SENT
F8: TOTAL | J8: =SUM(J5:J7) -> 3630 | K8: =SUM(K5:K7) -> 4231 | L8: =SUM(L5:L7) -> 3192 | M8: =SUM(M5:M7) -> 1039 | N8: =SUM(N5:N7) -> 3192 | O8: =SUM(O5:O7) -> 0 | P8: =SUM(P5:P7) -> 3707 | Q8: =SUM(Q5:Q7) -> 220
B10: F Line | C10: PLANT CODE | D10: LINE NO | E10: CON | F10: DESTINATION | G10: PO NO | H10: COLOR | I10: MATERIAL NO | J10: QTY | K10: CUT QTY | L10: Send to Wash / Dye | M10: Balance to Send | N10: Wash / Dye Received | O10: Balance to receive | P10: PACK/SHIP QTY | Q10: CTNS | R10: STATUS | T10: FI to be done by | U10: ASN | V10: WEIGHT | W10: WFX | X10: OCR | Y10: BOOKING NO | Z10: DRAFT
B11: L -8 | C11: V994 | D11: 10 | E11: PRLS/25/12441 | F11: JAPAN | G11: 4702056495 | H11: AUSTIN BLUE | I11: 710966294509 | J11: 20 | K11: 20 | L11: 20 | M11: 0 | N11: 20 | O11: 0 | P11: 20 | Q11: 1 | R11: Shipped | S11: Ready By - 13-01-2026 | U11: SENT | V11: DONE | W11: DONE | X11: DONE | Y11: IBKG0000220558 | Z11: SENT
B12: L -6 | C12: V994 | D12: 10 | E12: PRLS/25/12223 | F12: JAPAN | G12: 4702049213 | H12: 594C BLUE/WHITE | I12: 710B16388001 | J12: 890 | K12: 4842 | L12: 4832 | M12: 10 | N12: 4832 | O12: 0 | P12: 913 | Q12: 52 | R12: Shipped | S12: Ready By - 13-01-2026 | U12: SENT | V12: DONE | W12: DONE | X12: DONE | Z12: SENT
B13: L -6 | C13: V994 | D13: 20 | E13: PRLS/25/12225 | F13: JAPAN | G13: 4702049223 | H13: 5137F CHOCOLATE MOUSSE/WHITE | I13: 710B22228003 | J13: 760 | K13: 2468 | L13: 2025 | M13: 443 | N13: 2025 | O13: 0 | P13: 781 | Q13: 45 | R13: Shipped | S13: Ready By - 17-01-2026 | U13: SENT | V13: DONE | W13: DONE | X13: DONE
B14: L -6 | C14: V994 | D14: 10 | E14: PRLS/25/12339 | F14: JAPAN | G14: 4702049223 | H14: 5137B PINK/WHITE | I14: 710B22228002 | J14: 790 | K14: 2314 | L14: 2311 | M14: 3 | N14: 2311 | O14: 0 | P14: 792 | Q14: 45 | R14: Shipped | S14: Ready By - 16-01-2026 | U14: SENT | V14: DONE | W14: DONE | X14: DONE | Z14: SENT
B15: L -6 | C15: V994 | D15: 10 | E15: PRLS/25/12221 | F15: JAPAN | G15: 4702053672 | H15: BAYSIDE GREEN | I15: 710967669004 | J15: 630 | K15: 2502 | L15: 1217 | M15: 1285 | N15: 1217 | O15: 0 | P15: 644 | Q15: 38 | R15: Shipped | S15: Ready By - 19-01-2026 | U15: SENT | V15: DONE | W15: DONE | X15: DONE
F16: TOTAL | J16: =SUM(J11:J15) -> 3090 | K16: =SUM(K11:K15) -> 12146 | L16: =SUM(L11:L15) -> 10405 | M16: =SUM(M11:M15) -> 1741 | N16: =SUM(N11:N15) -> 10405 | O16: =SUM(O11:O15) -> 0 | P16: =SUM(P11:P15) -> 3150 | Q16: =SUM(Q11:Q15) -> 181
B18: F Line | C18: PLANT CODE | D18: LINE NO | E18: CON | F18: DESTINATION | G18: PO NO | H18: COLOR | I18: MATERIAL NO | J18: QTY | K18: CUT QTY | L18: Send to Wash / Dye | M18: Balance to Send | N18: Wash / Dye Received | O18: Balance to receive | P18: PACK/SHIP QTY | Q18: CTNS | R18: STATUS | T18: FI to be done by | U18: ASN | V18: WEIGHT | W18: WFX | X18: OCR | Y18: BOOKING NO | Z18: DRAFT
B19: L -8 | C19: V993 | D19: 10 | E19: PRLS/25/12436 | F19: KOREA | G19: 4702056494 | H19: POLO BLACK | I19: 710966294019 | J19: 29 | K19: 29 | L19: 29 | M19: 0 | N19: 29 | O19: 0 | P19: 29 | Q19: 2 | R19: Shipped | S19: Ready By - 13-01-2026 | U19: SENT | V19: DONE | W19: DONE | X19: DONE | Y19: IBKG0000220560 | Z19: SENT
B20: L -8 | C20: V993 | D20: 20 | E20: PRLS/25/12441 | F20: KOREA | G20: 4702056494 | H20: AUSTIN BLUE | I20: 710966294509 | J20: 259 | K20: 275 | L20: 275 | M20: 0 | N20: 275 | O20: 0 | P20: 259 | Q20: 15 | R20: Shipped | S20: Ready By - 13-01-2026 | U20: SENT | V20: DONE | W20: DONE | X20: DONE | Z20: SENT
F21: TOTAL | J21: =SUM(J19:J20) -> 288 | K21: =SUM(K19:K20) -> 304 | L21: =SUM(L19:L20) -> 304 | M21: =SUM(M19:M20) -> 0 | N21: =SUM(N19:N20) -> 304 | O21: =SUM(O19:O20) -> 0 | P21: =SUM(P19:P20) -> 288 | Q21: =SUM(Q19:Q20) -> 17
B23: F Line | C23: PLANT CODE | D23: LINE NO | E23: CON | F23: DESTINATION | G23: PO NO | H23: COLOR | I23: MATERIAL NO | J23: QTY | K23: CUT QTY | L23: Send to Wash / Dye | M23: Balance to Send | N23: Wash / Dye Received | O23: Balance to receive | P23: PACK/SHIP QTY | Q23: CTNS | R23: STATUS | T23: FI to be done by | U23: ASN | V23: WEIGHT | W23: WFX | X23: OCR | Y23: BOOKING NO | Z23: DRAFT
B24: L -5 | C24: V994 | D24: 10 | E24: PRLS/25/12210 | F24: JAPAN | G24: 4702053667 | H24: COOPER BROWN | I24: 710967632004 | J24: 940 | K24: 1024 | L24: 1021 | M24: 3 | N24: 1021 | O24: 0 | P24: 951 | Q24: 55 | R24: Shipped | S24: Ready By - 16-01-2026 | U24: SENT | V24: DONE | W24: DONE | X24: DONE | Y24: IBKG0000220559
F25: TOTAL | J25: =SUM(J24) -> 940 | K25: =SUM(K24) -> 1024 | L25: =SUM(L24) -> 1021 | M25: =SUM(M24) -> 3 | N25: =SUM(N24) -> 1021 | O25: =SUM(O24) -> 0 | P25: =SUM(P24) -> 951 | Q25: =SUM(Q24) -> 55
B27: F Line | C27: PLANT CODE | D27: LINE NO | E27: CON | F27: DESTINATION | G27: PO NO | H27: COLOR | I27: MATERIAL NO | J27: QTY | K27: CUT QTY | L27: Send to Wash / Dye | M27: Balance to Send | N27: Wash / Dye Received | O27: Balance to receive | P27: PACK/SHIP QTY | Q27: CTNS | R27: STATUS | T27: FI to be done by | U27: ASN | V27: WEIGHT | W27: WFX | X27: OCR | Y27: BOOKING NO | Z27: DRAFT
B28: L -8 | C28: NW00 | D28: 30 | E28: PRLS/25/12437 | F28: US | G28: 4702056488 | H28: AUSTIN BLUE | I28: 710966292032 | J28: 1209 | K28: 1450 | L28: =1450-230 -> 1220 | M28: 230 | N28: 1220 | O28: 0 | P28: 1219 | Q28: 73 | R28: Shipped | S28: Ready By - 19-01-2026 | U28: SENT | V28: DONE | W28: DONE | X28: DONE | Y28: IBKG0000220561
F29: TOTAL | J29: =SUM(J28) -> 1209 | K29: =SUM(K28) -> 1450 | L29: =SUM(L28) -> 1220 | M29: =SUM(M28) -> 230 | N29: =SUM(N28) -> 1220 | O29: =SUM(O28) -> 0 | P29: =SUM(P28) -> 1219 | Q29: =SUM(Q28) -> 73
B31: F Line | C31: PLANT CODE | D31: LINE NO | E31: CON | F31: DESTINATION | G31: PO NO | H31: COLOR | I31: MATERIAL NO | J31: QTY | K31: CUT QTY | L31: Send to Wash / Dye | M31: Balance to Send | N31: Wash / Dye Received | O31: Balance to receive | P31: PACK/SHIP QTY | Q31: CTNS | R31: STATUS | T31: FI to be done by | U31: ASN | V31: WEIGHT | W31: WFX | X31: OCR | Y31: BOOKING NO | Z31: DRAFT
B32: L -8 | C32: LA00 | D32: 30 | E32: PRLS/25/12437 | F32: US | G32: 4702055747 | H32: AUSTIN BLUE | I32: 710966292032CUX | J32: 36 | K32: 36 | L32: 36 | M32: 0 | N32: 36 | O32: 0 | P32: 36 | Q32: 3 | R32: Shipped | S32: Ready By - 19-01-2026 | U32: SENT | V32: DONE | W32: DONE | X32: DONE | Y32: IBKG0000220562 | Z32: SENT
B33: L -8 | C33: LA00 | D33: 30 | E33: PRLS/25/12437 | F33: US | G33: 4702055741 | H33: AUSTIN BLUE | I33: 710966292032AAA | J33: 64 | K33: 64 | L33: 64 | M33: 0 | N33: 64 | O33: 0 | P33: 64 | Q33: 8 | R33: Shipped | S33: Ready By - 19-01-2026 | U33: SENT | V33: DONE | W33: DONE | X33: DONE | Z33: SENT
B34: L -8 | C34: LA00 | D34: 30 | E34: PRLS/25/12437 | F34: US | G34: 4702055748 | H34: AUSTIN BLUE | I34: 710966292032CUY | J34: 48 | K34: 48 | L34: 48 | M34: 0 | N34: 48 | O34: 0 | P34: 48 | Q34: 4 | R34: Shipped | S34: Ready By - 19-01-2026 | U34: SENT | V34: DONE | W34: DONE | X34: DONE | Z34: SENT
B35: L -8 | C35: LA00 | D35: 30 | E35: PRLS/25/12437 | F35: US | G35: 4702055743 | H35: AUSTIN BLUE | I35: 710966292032ANN | J35: 488 | K35: 488 | L35: 488 | M35: 0 | N35: 488 | O35: 0 | P35: 488 | Q35: 61 | R35: Shipped | S35: Ready By - 19-01-2026 | U35: SENT | V35: DONE | W35: DONE | X35: DONE | Z35: SENT
B36: L -8 | C36: LA00 | D36: 30 | E36: PRLS/25/12437 | F36: US | G36: 4702055749 | H36: AUSTIN BLUE | I36: 710966292032CUZ | J36: 36 | K36: 36 | L36: 36 | M36: 0 | N36: 36 | O36: 0 | P36: 36 | Q36: 3 | R36: Shipped | S36: Ready By - 19-01-2026 | U36: SENT | V36: DONE | W36: DONE | X36: DONE | Z36: SENT
B37: L -8 | C37: LA00 | D37: 30 | E37: PRLS/25/12437 | F37: US | G37: 4702055742 | H37: AUSTIN BLUE | I37: 710966292032ANI | J37: 936 | K37: 988 | L37: 988 | M37: 0 | N37: 988 | O37: 0 | P37: 936 | Q37: 156 | R37: Shipped | S37: Ready By - 19-01-2026 | U37: SENT | V37: DONE | W37: DONE | X37: DONE | Z37: SENT
B38: L -8 | C38: LA00 | D38: 30 | E38: PRLS/25/12437 | F38: US | G38: 4702055750 | H38: AUSTIN BLUE | I38: 710966292032CVA | J38: 12 | K38: 12 | L38: 12 | M38: 0 | N38: 12 | O38: 0 | P38: 12 | Q38: 1 | R38: Shipped | S38: Ready By - 19-01-2026 | U38: SENT | V38: DONE | W38: DONE | X38: DONE | Z38: SENT
B39: L -8 | C39: LA00 | D39: 30 | E39: PRLS/25/12437 | F39: US | G39: 4702055745 | H39: AUSTIN BLUE | I39: 710966292032CRV | J39: 150 | K39: 155 | L39: 155 | M39: 0 | N39: 155 | O39: 0 | P39: 150 | Q39: 25 | R39: Shipped | S39: Ready By - 19-01-2026 | U39: SENT | V39: DONE | W39: DONE | X39: DONE | Z39: SENT
B40: L -8 | C40: LA00 | D40: 30 | E40: PRLS/25/12437 | F40: US | G40: 4702055744 | H40: AUSTIN BLUE | I40: 710966292032ARF | J40: 360 | K40: =380+21 -> 401 | L40: 401 | M40: 0 | N40: 401 | O40: 0 | P40: 360 | Q40: 60 | R40: Shipped | S40: Ready By - 19-01-2026 | U40: SENT | V40: DONE | W40: DONE | X40: DONE | Z40: SENT
B41: L -8 | C41: LA00 | D41: 30 | E41: PRLS/25/12437 | F41: US | G41: 4702055746 | H41: AUSTIN BLUE | I41: 710966292032CUW | J41: 12 | K41: 12 | L41: 12 | M41: 0 | N41: 12 | O41: 0 | P41: 12 | Q41: 1 | R41: Shipped | S41: Ready By - 19-01-2026 | U41: SENT | V41: DONE | W41: DONE | X41: DONE
F42: TOTAL | J42: =SUM(J32:J41) -> 2142 | K42: =SUM(K32:K41) -> 2240 | L42: =SUM(L32:L41) -> 2240 | M42: =SUM(M32:M41) -> 0 | N42: =SUM(N32:N41) -> 2240 | O42: =SUM(O32:O41) -> 0 | P42: =SUM(P32:P41) -> 2142 | Q42: =SUM(Q32:Q41) -> 322
B44: AIR BOOKING
B45: F Line | C45: PLANT CODE | D45: LINE NO | E45: CON | F45: DESTINATION | G45: PO NO | H45: COLOR | I45: MATERIAL NO | J45: QTY | K45: CUT QTY | L45: Send to Wash / Dye | M45: Balance to Send | N45: Wash / Dye Received | O45: Balance to receive | P45: PACK/SHIP QTY | Q45: CTNS | R45: STATUS | T45: FI to be done by | U45: ASN | V45: WEIGHT | W45: WFX | X45: OCR | Y45: BOOKING NO | Z45: DRAFT
B46: L -8 | C46: TO17 | D46: 30 | E46: PRLS/25/12437 | F46: CANADA | G46: 4702056489 | H46: AUSTIN BLUE | I46: 710966292032 | J46: 207 | P46: 207 | Q46: 14 | R46: SHIPPED | S46: Ready By - 19-01-2026 | U46: SENT | V46: DONE | W46: DONE | X46: DONE | Y46: IBKG0000227404
B47: L -5 | C47: CA10 | D47: 10 | E47: PRLS/25/12442 | F47: ITALY | G47: 4702056496 | H47: AUSTIN BLUE | I47: 710968912501 | J47: 524 | P47: 534 | Q47: 26 | R47: SHIPPED | S47: Ready By - 14-01-2026 | U47: SENT | V47: DONE | W47: DONE | X47: DONE | Y47: IBKG0000227406
...

Sheet CDD - 18-01-2026-SHIPPED
H2: =NOW()-TRUNC(NOW()) -> 0.61871759 | I2: G Total | J2: =SUBTOTAL(9,#REF!,#REF!,#REF!,#REF!,#REF!,#REF!,#REF!,J78:J79,J41:J43,#REF!) -> #REF! | K2: =SUBTOTAL(9,#REF!,#REF!,#REF!,#REF!,#REF!,#REF!,#REF!,K78:K79,K41:K43,#REF!) -> #REF! | L2: =SUBTOTAL(9,#REF!,#REF!,#REF!,#REF!,#REF!,#REF!,#REF!,L78:L79,L41:L43,#REF!) -> #REF! | M2: =SUBTOTAL(9,#REF!,#REF!,#REF!,#REF!,#REF!,#REF!,#REF!,M78:M79,M41:M43,#REF!) -> #REF! | N2: =SUBTOTAL(9,#REF!,#REF!,#REF!,#REF!,#REF!,#REF!,#REF!,N78:N79,N41:N43,#REF!) -> #REF! | O2: =SUBTOTAL(9,#REF!,#REF!,#REF!,#REF!,#REF!,#REF!,#REF!,O78:O79,O41:O43,#REF!) -> #REF! | P2: =SUBTOTAL(9,#REF!,#REF!,#REF!,#REF!,#REF!,#REF!,#REF!,P78:P79,P41:P43,#REF!) -> #REF! | Q2: =SUBTOTAL(9,#REF!,#REF!,#REF!,#REF!,#REF!,#REF!,#REF!,Q78:Q79,Q41:Q43,#REF!) -> #REF! | R2: =SUBTOTAL(9,#REF!,#REF!,#REF!,#REF!,#REF!,#REF!,#REF!,R80,R44,#REF!) -> #REF!
E3: SEA - FOB - CHENNAI | F3: TRUCKOUT ON - 30.12.2025 | H3: CDD - 11.01.2026
B4: F Line | C4: PLANT CODE | D4: LINE NO | E4: CON | F4: DESTINATION | G4: PO NO | H4: COLOR | I4: MATERIAL NO | J4: QTY | K4: CUT QTY | L4: Send to Wash / Dye | M4: Balance to Send | N4: Wash / Dye Received | O4: Balance to receive | P4: PACK/SHIP QTY | Q4: CTNS | R4: STATUS | S4: FI to be done by | T4: ASN | U4: WEIGHT | V4: WFX | W4: OCR | X4: BOOKING NO | Y4: NEW BOOKING NO | Z4: INV NO | AA4: DRAFT
B5: 5 | C5: TO17 | D5: 20 | E5: PRLS/25/12434 | F5: CANADA | G5: 4702056489 | H5: POLO BLACK | I5: 710966292015 | J5: 12 | P5: 12 | Q5: 1 | R5: To City office | S5: VQA | T5: SENT | U5: DONE | V5: DONE | W5: DONE | X5: IBKG0000216865 | Y5: IBKG0000226916 | AA5: SENT
F6: TOTAL | J6: =SUM(J5) -> 12 | K6: =SUM(K5) -> 0 | L6: =SUM(L5) -> 0 | M6: =SUM(M5) -> 0 | N6: =SUM(N5) -> 0 | O6: =SUM(O5) -> 0 | P6: =SUM(P5) -> 12 | Q6: =SUM(Q5) -> 1
E9: AIR BOOKING
B10: F Line | C10: PLANT CODE | D10: LINE NO | E10: CON | F10: DESTINATION | G10: PO NO | H10: COLOR | I10: MATERIAL NO | J10: QTY | K10: CUT QTY | L10: Send to Wash / Dye | M10: Balance to Send | N10: Wash / Dye Received | O10: Balance to receive | P10: PACK/SHIP QTY | Q10: CTNS | R10: STATUS | S10: FI to be done by | T10: ASN | U10: WEIGHT | V10: WFX | W10: OCR | X10: BOOKING NO | Y10: DO | Z10: INV NO | AA10: DRAFT
E11: PRLS/25/10999 | F11: KOREA | G11: 4702008417 | H11: INDIGO BLUE/CREAM MULTI | I11: 782P05370001 | J11: 184 | P11: 200 | Q11: 9 | R11: Shipped | T11: DONE | U11: DONE | V11: DONE | W11: DONE | X11: IBKG0000223075 | AA11: SENT
E12: PRLS/25/10999 | F12: JAPAN | G12: 4702008418 | H12: INDIGO BLUE/CREAM MULTI | I12: 782P05370001 | J12: 93 | P12: 93 | Q12: 4 | R12: Shipped | T12: DONE | U12: DONE | V12: DONE | W12: DONE | X12: IBKG0000223072 | AA12: SENT
E13: PRLS/25/10999 | F13: HK | G13: 4702008416 | H13: INDIGO BLUE/CREAM MULTI | I13: 782P05370001 | J13: 93 | P13: 93 | Q13: 4 | R13: To City office | T13: SENT | U13: DONE | V13: DONE | W13: DONE | X13: IBKG0000218612 | AA13: SENT
E14: PRLS/25/12433 | F14: CANADA | G14: 4702056489 | H14: CARMEL PINK | I14: 710966292008 | J14: 25 | P14: 25 | Q14: 2 | R14: To City office | T14: SENT | U14: DONE | V14: DONE | W14: DONE | X14: IBKG0000223079 | AA14: SENT
J15: =SUM(J11:J14) -> 395 | P15: =SUM(P11:P14) -> 411 | Q15: =SUM(Q11:Q14) -> 19
B19: F Line | C19: PLANT CODE | D19: LINE NO | E19: CON | F19: DESTINATION | G19: PO NO | H19: COLOR | I19: MATERIAL NO | J19: QTY | K19: CUT QTY | L19: Send to Wash / Dye | M19: Balance to Send | N19: Wash / Dye Received | O19: Balance to receive | P19: PACK/SHIP QTY | Q19: CTNS | R19: STATUS | S19: FI to be done by | T19: ASN | U19: WEIGHT | V19: WFX | W19: OCR | X19: BOOKING NO
B21: RRL | C21: HD00 | D21: 10 | E21: PRLS/25/10999 | F21: US | G21: 4702008414 | H21: INDIGO BLUE/CREAM MULTI | I21: 782P05370001 | J21: 162 | P21: 169 | Q21: 8 | R21: Shipped | S21: VQA | T21: SENT | V21: DONE | W21: DONE | X21: IBKG0000218607
F22: TOTAL | J22: =SUM(J21) -> 162 | K22: =SUM(K21) -> 0 | L22: =SUM(L21) -> 0 | M22: =SUM(M21) -> 0 | N22: =SUM(N21) -> 0 | O22: =SUM(O21) -> 0 | P22: =SUM(P21) -> 169 | Q22: =SUM(Q21) -> 8
B24: RATIO | C24: LA00 | D24: 10 | E24: PRLS/25/12433 | F24: US | G24: 4702055743 | H24: CARMEL PINK | I24: 710966292008ANN | J24: 400 | P24: 400 | Q24: 50 | R24: Shipped | S24: VQA | T24: SENT | U24: DONE | V24: DONE | W24: DONE | X24: IBKG0000218608
B25: RATIO | C25: LA00 | D25: 10 | E25: PRLS/25/12433 | F25: US | G25: 4702055744 | H25: CARMEL PINK | I25: 710966292008ARF | J25: 396 | P25: 396 | Q25: 66 | R25: Shipped | S25: VQA | T25: SENT | U25: DONE | V25: DONE | W25: DONE
B26: RATIO | C26: LA00 | D26: 10 | E26: PRLS/25/12433 | F26: US | G26: 4702055741 | H26: CARMEL PINK | I26: 710966292008AAA | J26: 48 | P26: 48 | Q26: 6 | R26: Shipped | S26: VQA | T26: SENT | U26: DONE | V26: DONE | W26: DONE
B27: RATIO | C27: LA00 | D27: 10 | E27: PRLS/25/12433 | F27: US | G27: 4702055742 | H27: CARMEL PINK | I27: 710966292008ANI | J27: 888 | P27: 888 | Q27: 148 | R27: Shipped | S27: VQA | T27: SENT | U27: DONE | V27: DONE | W27: DONE
B28: RATIO | C28: LA00 | D28: 10 | E28: PRLS/25/12433 | F28: US | G28: 4702055746 | H28: CARMEL PINK | I28: 710966292008CUW | J28: 24 | P28: 24 | Q28: 2 | R28: Shipped | S28: VQA | T28: SENT | U28: DONE | V28: DONE | W28: DONE
B29: RATIO | C29: LA00 | D29: 10 | E29: PRLS/25/12433 | F29: US | G29: 4702055747 | H29: CARMEL PINK | I29: 710966292008CUX | J29: 72 | P29: 72 | Q29: 6 | R29: Shipped | S29: VQA | T29: SENT | U29: DONE | V29: DONE | W29: DONE
B30: RATIO | C30: LA00 | D30: 10 | E30: PRLS/25/12433 | F30: US | G30: 4702055748 | H30: CARMEL PINK | I30: 710966292008CUY | J30: 96 | P30: 96 | Q30: 8 | R30: Shipped | S30: VQA | T30: SENT | U30: DONE | V30: DONE | W30: DONE
B31: RATIO | C31: LA00 | D31: 10 | E31: PRLS/25/12433 | F31: US | G31: 4702055750 | H31: CARMEL PINK | I31: 710966292008CVA | J31: 36 | P31: 36 | Q31: 3 | R31: Shipped | S31: VQA | T31: SENT | U31: DONE | V31: DONE | W31: DONE
B32: RATIO | C32: LA00 | D32: 10 | E32: PRLS/25/12433 | F32: US | G32: 4702055749 | H32: CARMEL PINK | I32: 710966292008CUZ | J32: 60 | P32: 60 | Q32: 5 | R32: Shipped | S32: VQA | T32: SENT | U32: DONE | V32: DONE | W32: DONE
B33: RATIO | C33: LA00 | D33: 10 | E33: PRLS/25/12433 | F33: US | G33: 4702055745 | H33: CARMEL PINK | I33: 710966292008CRV | J33: 168 | P33: 168 | Q33: 28 | R33: Shipped | S33: VQA | T33: SENT | U33: DONE | V33: DONE | W33: DONE
B34: RATIO | C34: LA00 | D34: 10 | E34: PRLS/25/12438 | F34: US | G34: 4702055752 | H34: POLO BLACK | I34: 710966293015CUX | J34: 60 | P34: 60 | Q34: 5 | R34: Shipped | S34: VQA | T34: SENT | U34: DONE | V34: DONE | W34: DONE
B35: RATIO | C35: LA00 | D35: 10 | E35: PRLS/25/12438 | F35: US | G35: 4702055753 | H35: POLO BLACK | I35: 710966293015CUY | J35: 96 | P35: 96 | Q35: 8 | R35: Shipped | S35: VQA | T35: SENT | U35: DONE | V35: DONE | W35: DONE
B36: RATIO | C36: LA00 | D36: 10 | E36: PRLS/25/12438 | F36: US | G36: 4702055754 | H36: POLO BLACK | I36: 710966293015CUZ | J36: 72 | P36: 72 | Q36: 6 | R36: Shipped | S36: VQA | T36: SENT | U36: DONE | V36: DONE | W36: DONE
... B38: RATIO | C38: LA00 | D38: 10 | E38: PRLS/25/12438 | F38: US | G38: 4702055755 | H38: POLO BLACK | I38: 710966293015CVA | J38: 48 | P38: 48 | Q38: 4 | R38: Shipped | S38: VQA | T38: SENT | U38: DONE | V38: DONE | W38: DONE
F39: TOTAL | J39: =SUM(J24:J38) -> 2488 | K39: =SUM(K24:K38) -> 0 | L39: =SUM(L24:L38) -> 0 | M39: =SUM(M24:M38) -> 0 | N39: =SUM(N24:N38) -> 0 | O39: =SUM(O24:O38) -> 0 | P39: =SUM(P24:P38) -> 2488 | Q39: =SUM(Q24:Q38) -> 347
C41: V994 | D41: 20 | E41: PRLS/25/12140 | F41: JAPAN | G41: 4702043045 | H41: 7188B BLUE WHITE | I41: 710B15594005 | J41: 446 | P41: 455 | Q41: 26 | R41: Shipped | S41: VQA | T41: SENT | U41: DONE | V41: DONE | W41: DONE | X41: IBKG0000218613
C42: V994 | D42: 30 | E42: PRLS/25/12141 | F42: JAPAN | G42: 4702043045 | H42: 7188E COASTAL BEIGE WHITE | I42: 710B15594006 | J42: 508 | P42: 522 | Q42: 29 | R42: Shipped | S42: VQA | T42: SENT | U42: DONE | V42: DONE | W42: DONE
C43: V994 | D43: 10 | E43: PRLS/25/12139 | F43: JAPAN | G43: 4702043045 | H43: 7188A WHITE BLUE | I43: 710B15594004 | J43: 45 | P43: 45 | Q43: 3 | R43: Shipped | S43: VQA | T43: SENT | U43: DONE | V43: DONE | W43: DONE
F44: TOTAL | J44: =SUM(J41:J43) -> 999 | K44: =SUM(K41:K43) -> 0 | L44: =SUM(L41:L43) -> 0 | M44: =SUM(M41:M43) -> 0 | N44: =SUM(N41:N43) -> 0 | O44: =SUM(O41:O43) -> 0 | P44: =SUM(P41:P43) -> 1022 | Q44: =SUM(Q41:Q43) -> 58
C47: PLANT CODE | D47: LINE NO | E47: CON | F47: DESTINATION | G47: PO NO | H47: COLOR | I47: MATERIAL NO | J47: QTY | K47: CUT QTY | L47: Send to Wash / Dye | M47: Balance to Send | N47: Wash / Dye Received | O47: Balance to receive | P47: PACK/SHIP QTY | Q47: CTNS | R47: STATUS as on 7th Jan | S47: FI to be done by | T47: ASN | U47: WEIGHT | V47: WFX | W47: OCR | X47: BOOKING NO
C48: CA10 | D48: 10 | E48: PRLS/25/12198 | F48: ITALY | G48: 4702049202 | H48: 6707A NAVY/GREEN MULTI | I48: 710965825001 | J48: 30 | P48: 30 | Q48: 3 | R48: Shipped | S48: VQA | T48: SENT | U48: DONE | V48: DONE | W48: DONE | X48: IBKG0000218603
C49: CA10 | D49: 20 | E49: PRLS/25/12199 | F49: ITALY | G49: 4702049202 | H49: 6707B RED/GREEN MULTI | I49: 710965825002 | J49: 30 | P49: 30 | Q49: 3 | R49: Shipped | S49: VQA | T49: SENT | U49: DONE | V49: DONE | W49: DONE
C50: CA10 | D50: 30 | E50: PRLS/25/12201 | F50: ITALY | G50: 4702049202 | H50: 6707C TURQUISE/RED MULTI | I50: 710965825003 | J50: 30 | P50: 30 | Q50: 3 | R50: Shipped | S50: VQA | T50: SENT | U50: DONE | V50: DONE | W50: DONE
F51: TOTAL | J51: =SUM(J48:J50) -> 90 | K51: =SUM(K48:K50) -> 0 | L51: =SUM(L48:L50) -> 0 | M51: =SUM(M48:M50) -> 0 | N51: =SUM(N48:N50) -> 0 | O51: =SUM(O48:O50) -> 0 | P51: =SUM(P48:P50) -> 90 | Q51: =SUM(Q48:Q50) -> 9
C53: CA20 | D53: 10 | E53: PRLS/25/12198 | F53: ITALY | G53: 4702049203 | H53: 6707A NAVY/GREEN MULTI | I53: 710965825001 | J53: 950 | P53: 941 | Q53: 50 | R53: Shipped | S53: VQA | T53: SENT | U53: DONE | V53: DONE | W53: DONE | X53: IBKG0000218604
...

Sheet CDD - 11-01-2026 - SHIPPED
H2: =NOW()-TRUNC(NOW()) -> 0.61871759 | I2: G Total | J2: =SUBTOTAL(9,J52:J62,J66:J72,J76,J80,J5,J10) -> 25608 | K2: =SUBTOTAL(9,K52:K64,#REF!,#REF!,K5:K50) -> #REF! | L2: =SUBTOTAL(9,L52:L64,#REF!,#REF!,L5:L50) -> #REF! | M2: =SUBTOTAL(9,M52:M64,#REF!,#REF!,M5:M50) -> #REF! | N2: =SUBTOTAL(9,N52:N64,#REF!,#REF!,N5:N50) -> #REF! | O2: =SUBTOTAL(9,O52:O64,#REF!,#REF!,O5:O50) -> #REF! | P2: =SUBTOTAL(9,P52:P62,P66:P72,P76,P80,P5,P10) -> 25661 | Q2: =SUBTOTAL(9,Q52:Q62,Q66:Q72,Q76,Q80,Q5,Q10) -> 1432 | R2: =P2/J2*100 -> 100.20697
E3: SEA - FOB - CHENNAI | F3: TRUCKOUT ON - 30.12.2025 | H3: CDD - 11.01.2026
B4: F Line | C4: PLANT CODE | D4: LINE NO | E4: CON | F4: DESTINATION | G4: PO NO | H4: COLOR | I4: MATERIAL NO | J4: QTY | K4: CUT QTY | L4: Send to Wash / Dye | M4: Balance to Send | N4: Wash / Dye Received | O4: Balance to receive | P4: PACK/SHIP QTY | Q4: CTNS | R4: STATUS | S4: FI to be done by | T4: ASN | U4: WEIGHT | V4: WFX | W4: OCR | X4: BOOKING NO | Y4: DO | Z4: INV NO | AA4: DRAFT
B5: 5 | C5: TO17 | D5: 20 | E5: PRLS/25/12434 | F5: CANADA | G5: 4702056489 | H5: 5463 WHITE/YELLOW MULTI | I5: 710966292015 | J5: 12 | P5: 12 | Q5: 1 | R5: Ready to ship | S5: VQA | T5: DONE | V5: DONE | W5: DONE | X5: IBKG0000216865 | AA5: SENT
F6: TOTAL | J6: =SUM(J5) -> 12 | K6: =SUM(K5) -> 0 | L6: =SUM(L5) -> 0 | M6: =SUM(M5) -> 0 | N6: =SUM(N5) -> 0 | O6: =SUM(O5) -> 0 | P6: =SUM(P5) -> 12 | Q6: =SUM(Q5) -> 1
E8: AIR - FOB -B.LORE | F8: TRUCKOUT ON - 30.12.2025 | H8: CDD - 11.01.2026
B9: Line | C9: PLANT CODE | D9: LINE NO | E9: CON | F9: DESTINATION | G9: PO NO | H9: COLOR | I9: MATERIAL NO | J9: QTY | K9: CUT QTY | L9: Send to Wash / Dye | M9: Balance to Send | N9: Wash / Dye Received | O9: Balance to receive | P9: PACK/SHIP QTY | Q9: CTNS | R9: STATUS | S9: FI to be done by | T9: ASN | U9: WEIGHT | V9: WFX | W9: OCR | X9: BOOKING NO | Y9: DO | Z9: INV NO
B10: 5 | C10: PF00 | D10: 10 | E10: PRLS/25/12333 | F10: US | G10: 4702049225 | H10: 6555E KEY WEST WHITE | I10: 710B22363001 | J10: 100 | P10: 100 | Q10: 7 | R10: SHIPPED TO CITY OFFICE | S10: VQA | T10: DONE | V10: Done | W10: Done | X10: IBKG0000219578 | AA10: SENT
F11: TOTAL | J11: =SUM(J10) -> 100 | K11: =SUM(K10) -> 0 | L11: =SUM(L10) -> 0 | M11: =SUM(M10) -> 0 | N11: =SUM(N10) -> 0 | O11: =SUM(O10) -> 0 | P11: =SUM(P10) -> 100 | Q11: =SUM(Q10) -> 7
H14: GRAND TOTAL | J14: =+J6+J11 -> 112 | K14: =+K6+K11 -> 0 | L14: =+L6+L11 -> 0 | M14: =+M6+M11 -> 0 | N14: =+N6+N11 -> 0 | O14: =+O6+O11 -> 0 | P14: =+P6+P11 -> 112 | Q14: =+Q6+Q11 -> 8
I18: 730
I19: 737
B21: Line | C21: PLANT CODE | D21: LINE NO | E21: CON | F21: DESTINATION | G21: PO NO | H21: COLOR | I21: MATERIAL NO | J21: QTY | K21: CUT QTY | L21: Send to Wash / Dye | M21: Balance to Send | N21: Wash / Dye Received | O21: Balance to receive | P21: PACK/SHIP QTY | Q21: CTNS | R21: STATUS | S21: FI to be done by | T21: ASN | U21: WEIGHT | V21: WFX | W21: OCR | X21: BOOKING NO | Y21: DO | Z21: INV NO
B22: 6 | C22: PF00 | D22: 10 | E22: PRLS/25/12211 | F22: US | G22: 4702053661 | H22: CARMEL PINK | I22: 710967632006 | J22: 3036 | P22: 3090 | Q22: 179 | R22: SHIPPED | S22: - | T22: DONE | U22: DONE | V22: DONE | W22: DONE | X22: IBKG0000216225
B23: 5 | C23: PF00 | D23: 10 | E23: PRLS/25/12333 | F23: US | G23: 4702049224 | H23: 6555E KEY WEST WHITE | I23: 710B22363001 | J23: 3764 | P23: 3851 | Q23: 221 | R23: SHIPPED | S23: - | T23: DONE | U23: DONE | V23: DONE | W23: DONE
F24: TOTAL | J24: =SUM(J22:J23) -> 6800 | K24: =SUM(#REF!) -> #REF! | L24: =SUM(#REF!) -> #REF! | M24: =SUM(#REF!) -> #REF! | N24: =SUM(#REF!) -> #REF! | O24: =SUM(#REF!) -> #REF! | P24: =SUM(P22:P23) -> 6941 | Q24: =SUM(Q22:Q23) -> 400
B26: Line | C26: PLANT CODE | D26: LINE NO | E26: CON | F26: DESTINATION | G26: PO NO | H26: COLOR | I26: MATERIAL NO | J26: QTY | K26: CUT QTY | L26: Send to Wash / Dye | M26: Balance to Send | N26: Wash / Dye Received | O26: Balance to receive | P26: PACK/SHIP QTY | Q26: CTNS | R26: STATUS | S26: FI to be done by | T26: ASN | U26: WEIGHT | V26: WFX | W26: OCR | X26: BOOKING NO | Y26: DO | Z26: INV NO
B27: 5 | C27: LA00 | D27: 20 | E27: PRLS/25/12434 | F27: US | G27: 4702055741 | H27: POLO BLACK | I27: 710966292015 | J27: 88 | P27: 88 | Q27: 11 | R27: SHIPPED | S27: - | T27: DONE | U27: DONE | V27: DONE | W27: DONE | X27: IBKG0000216226 | AA27: Sent
B28: 5 | C28: LA00 | D28: 20 | E28: PRLS/25/12434 | F28: US | G28: 4702055742 | H28: POLO BLACK | I28: 710966292015 | J28: 912 | P28: 912 | Q28: 152 | R28: SHIPPED | S28: - | T28: DONE | U28: DONE | V28: DONE | W28: DONE | AA28: Sent
B29: 5 | C29: LA00 | D29: 20 | E29: PRLS/25/12434 | F29: US | G29: 4702055743 | H29: POLO BLACK | I29: 710966292015 | J29: 472 | P29: 472 | Q29: 59 | R29: SHIPPED | S29: - | T29: DONE | U29: DONE | V29: DONE | W29: DONE | AA29: Sent
B30: 5 | C30: LA00 | D30: 20 | E30: PRLS/25/12434 | F30: US | G30: 4702055744 | H30: POLO BLACK | I30: 710966292015 | J30: 402 | P30: 402 | Q30: 67 | R30: SHIPPED | S30: - | T30: DONE | U30: DONE | V30: DONE | W30: DONE | AA30: Sent
B31: 5 | C31: LA00 | D31: 20 | E31: PRLS/25/12434 | F31: US | G31: 4702055745 | H31: POLO BLACK | I31: 710966292015 | J31: 144 | P31: 144 | Q31: 24 | R31: SHIPPED | S31: - | T31: DONE | U31: DONE | V31: DONE | W31: DONE | AA31: Sent
B32: 5 | C32: LA00 | D32: 20 | E32: PRLS/25/12434 | F32: US | G32: 4702055746 | H32: POLO BLACK | I32: 710966292015 | J32: 36 | P32: 36 | Q32: 3 | R32: SHIPPED | S32: - | T32: DONE | U32: DONE | V32: DONE | W32: DONE | AA32: Sent
B33: 5 | C33: LA00 | D33: 20 | E33: PRLS/25/12434 | F33: US | G33: 4702055747 | H33: POLO BLACK | I33: 710966292015 | J33: 108 | P33: 108 | Q33: 9 | R33: SHIPPED | S33: - | T33: DONE | U33: DONE | V33: DONE | W33: DONE | AA33: Sent
B34: 5 | C34: LA00 | D34: 20 | E34: PRLS/25/12434 | F34: US | G34: 4702055748 | H34: POLO BLACK | I34: 710966292015 | J34: 132 | P34: 132 | Q34: 11 | R34: SHIPPED | S34: - | T34: DONE | U34: DONE | V34: DONE | W34: DONE | AA34: Sent
B35: 5 | C35: LA00 | D35: 20 | E35: PRLS/25/12434 | F35: US | G35: 4702055749 | H35: POLO BLACK | I35: 710966292015 | J35: 84 | P35: 84 | Q35: 7 | R35: SHIPPED | S35: - | T35: DONE | U35: DONE | V35: DONE | W35: DONE | AA35: Sent
B36: 5 | C36: LA00 | D36: 20 | E36: PRLS/25/12434 | F36: US | G36: 4702055750 | H36: POLO BLACK | I36: 710966292015 | J36: 36 | P36: 36 | Q36: 3 | R36: SHIPPED | S36: - | T36: DONE | U36: DONE | V36: DONE | W36: DONE | AA36: Sent
F37: TOTAL | J37: =SUM(J27:J36) -> 2414 | P37: =SUM(P27:P36) -> 2414 | Q37: =SUM(Q27:Q36) -> 346
B39: Line | C39: PLANT CODE | D39: LINE NO | E39: CON | F39: DESTINATION | G39: PO NO | H39: COLOR | I39: MATERIAL NO | J39: QTY | K39: CUT QTY | L39: Send to Wash / Dye | M39: Balance to Send | N39: Wash / Dye Received | O39: Balance to receive | P39: PACK/SHIP QTY | Q39: CTNS | R39: STATUS | S39: FI to be done by | T39: ASN | U39: WEIGHT | V39: WFX | W39: OCR | X39: BOOKING NO | Y39: DO | Z39: INV NO
B40: 5 | C40: CA10 | D40: 10 | E40: PRLS/25/12334 | F40: US | G40: 4702048642 | H40: WHITE/YELLOW MULTI | I40: 710B23578001 | J40: 100 | P40: 100 | Q40: 2 | R40: SHIPPED | S40: VQA | T40: DONE | U40: DONE | V40: DONE | W40: DONE | X40: IBKG0000217978 | AA40: SENT
B41: 5 | C41: CA10 | D41: 10 | E41: PRLS/25/12337 | F41: US | G41: 4702048645 | H41: WHITE/YELLOW MULTI | I41: 711B23578001 | J41: 100 | P41: 100 | Q41: 4 | R41: SHIPPED | S41: VQA | T41: DONE | U41: DONE | V41: DONE | W41: DONE | AA41: SENT
F42: TOTAL | J42: =SUM(J40:J41) -> 200 | K42: =SUM(K40:K41) -> 0 | L42: =SUM(L40:L41) -> 0 | M42: =SUM(M40:M41) -> 0 | N42: =SUM(N40:N41) -> 0 | O42: =SUM(O40:O41) -> 0 | P42: =SUM(P40:P41) -> 200 | Q42: =SUM(Q40:Q41) -> 6
B44: Line | C44: PLANT CODE | D44: LINE NO | E44: CON | F44: DESTINATION | G44: PO NO | H44: COLOR | I44: MATERIAL NO | J44: QTY | K44: CUT QTY | L44: Send to Wash / Dye | M44: Balance to Send | N44: Wash / Dye Received | O44: Balance to receive | P44: PACK/SHIP QTY | Q44: CTNS | R44: STATUS | S44: FI to be done by | T44: ASN | U44: WEIGHT | V44: WFX | W44: OCR | X44: BOOKING NO | Y44: DO | Z44: INV NO
B45: 5 | C45: TO40 | D45: 10 | E45: PRLS/25/12333 | F45: CANADA | G45: 4702049226 | H45: 6555E KEY WEST WHITE | I45: 710B22363001 | J45: 336 | P45: 339 | Q45: 21 | R45: SHIPPED | S45: VQA | T45: DONE | U45: DONE | V45: DONE | X45: IBKG0000216867 | AA45: SENT
F46: TOTAL | J46: =SUM(J45) -> 336 | K46: =SUM(K45) -> 0 | L46: =SUM(L45) -> 0 | M46: =SUM(M45) -> 0 | N46: =SUM(N45) -> 0 | O46: =SUM(O45) -> 0 | P46: =SUM(P45) -> 339 | Q46: =SUM(Q45) -> 21
B48: Line | C48: PLANT CODE | D48: LINE NO | E48: CON | F48: DESTINATION | G48: PO NO | H48: COLOR | I48: MATERIAL NO | J48: QTY | K48: CUT QTY | L48: Send to Wash / Dye | M48: Balance to Send | N48: Wash / Dye Received | O48: Balance to receive | P48: PACK/SHIP QTY | Q48: CTNS | R48: STATUS | S48: FI to be done by | T48: ASN | U48: WEIGHT | V48: WFX | W48: OCR | X48: BOOKING NO | Y48: DO | Z48: INV NO
B49: 5 | C49: NW00 | D49: 20 | E49: PRLS/25/12434 | F49: US | G49: 4702056488 | H49: POLO BLACK | I49: 710966292015 | J49: 2610 | P49: 2659 | Q49: 154 | R49: SHIPPED | S49: QIMA | T49: DONE | U49: Done | V49: Done | X49: IBKG0000216224 | AA49: SENT
F50: TOTAL | J50: =SUM(J49:J49) -> 2610 | K50: =SUM(#REF!) -> #REF! | L50: =SUM(#REF!) -> #REF! | M50: =SUM(#REF!) -> #REF! | N50: =SUM(#REF!) -> #REF! | O50: =SUM(#REF!) -> #REF! | P50: =SUM(P49:P49) -> 2659 | Q50: =SUM(Q49:Q49) -> 154
B52: 6 | C52: CA20 | D52: 10 | E52: PRLS/25/12206 | F52: ITALY | G52: 4702049206 | H52: 5137G COASTAL BEIGE/WHITE | I52: 710982798002 | J52: 4665 | K52: =P52 -> 4767 | L52: =K52 -> 4767 | M52: 0 | N52: =L52 -> 4767 | O52: 0 | P52: 4767 | Q52: 272 | R52: SHIPPED | S52: VQA | T52: Done | U52: Done | V52: Done | W52: Done | X52: IBKG0000216213 | Y52: SMAAS088566 - | AA52: SENT
B53: 6 | C53: CA20 | D53: 10 | E53: PRLS/25/12329 | F53: ITALY | G53: 4702049730 | H53: 5137G COASTAL BEIGE/WHITE | I53: 710982798002CTR | J53: 396 | K53: =P53 -> 396 | L53: =K53 -> 396 | M53: 0 | N53: =L53 -> 396 | O53: 0 | P53: 396 | Q53: 18 | R53: SHIPPED | S53: VQA | T53: Done | U53: Done | V53: Done | W53: Done | AA53: SENT
...

Sheet CDD - 04-01-2026-SHIPPED
H2: =NOW()-TRUNC(NOW()) -> 0.61871759 | I2: G Total | J2: =SUBTOTAL(9,J5:J8,J12,J16,J20:J22,J26:J29,J33:J43,J47:J49,J53:J59,J64:J65,J70) -> 33930 | K2: =SUBTOTAL(9,K5:K16,#REF!,K20:K29,K33:K65) -> #REF! | L2: =SUBTOTAL(9,L5:L16,#REF!,L20:L29,L33:L65) -> #REF! | M2: =SUBTOTAL(9,M5:M16,#REF!,M20:M29,M33:M65) -> #REF! | N2: =SUBTOTAL(9,N5:N16,#REF!,N20:N29,N33:N65) -> #REF! | O2: =SUBTOTAL(9,O5:O16,#REF!,O20:O29,O33:O65) -> #REF! | P2: =SUBTOTAL(9,P5:P8,P12,P16,P20:P22,P26:P29,P33:P43,P47:P49,P53:P59,P64:P65,P70) -> 34546 | Q2: =SUBTOTAL(9,Q5:Q8,Q12,Q16,Q20:Q22,Q26:Q29,Q33:Q43,Q47:Q49,Q53:Q59,Q64:Q65,Q70:Q71) -> 1857 | R2: =P2/J2*100 -> 101.8155
E3: SEA - FOB - CHENNAI | F3: TRUCKOUT ON - 25.12.2025 | H3: CDD - 04.01.2026
B4: Line | C4: PLANT CODE | D4: LINE NO | E4: CON | F4: DESTINATION | G4: PO NO | H4: COLOR | I4: MATERIAL NO | J4: QTY | K4: CUT QTY | L4: Send to Wash / Dye | M4: Balance to Send | N4: Wash / Dye Received | O4: Balance to receive | P4: PACK/SHIP QTY | Q4: CTNS | R4: STATUS | S4: FI to be done by | T4: ASN | U4: WEIGHT | V4: WFX | W4: OCR | X4: BOOKING NO | Y4: DO | Z4: INV NO
B5: 6 | C5: TO40 | D5: 10 | E5: PRLS/25/12130 | F5: CANADA | G5: 4702043032 | H5: 7188D LAVENDER WHITE | I5: 710978098501 | J5: 36 | K5: =P5 -> 36 | L5: =K5 -> 36 | M5: 0 | N5: =L5 -> 36 | O5: 0 | P5: 36 | Q5: 4 | R5: Shipped | S5: QIMA | T5: SENT | U5: DONE | V5: DONE | W5: DONE | X5: IBKG0000213014
B6: 6 | C6: TO40 | D6: 20 | E6: PRLS/25/12132 | F6: CANADA | G6: 4702043032 | H6: 7188A WHITE BLUE | I6: 710978098503 | J6: 48 | K6: =P6 -> 48 | L6: =K6 -> 48 | M6: 0 | N6: =L6 -> 48 | O6: 0 | P6: 48 | Q6: 3 | R6: Shipped | S6: VQA | T6: SENT | U6: DONE | V6: DONE | W6: DONE
B7: 6 | C7: TO40 | D7: 30 | E7: PRLS/25/12133 | F7: CANADA | G7: 4702043032 | H7: 7188B BLUE WHITE | I7: 710978098505 | J7: 42 | K7: =P7 -> 42 | L7: =K7 -> 42 | M7: 0 | N7: =L7 -> 42 | O7: 0 | P7: 42 | Q7: 3 | R7: Shipped | S7: VQA | T7: SENT | U7: DONE | V7: DONE | W7: DONE
B8: 5 | C8: TO40 | D8: 40 | E8: PRLS/25/12134 | F8: CANADA | G8: 4702043032 | H8: 7188G NEW CLASSIC NAVY WHITE | I8: 710978098508 | J8: 42 | K8: =P8 -> 42 | L8: =K8 -> 42 | M8: 0 | N8: =L8 -> 42 | O8: 0 | P8: 42 | Q8: 3 | R8: Shipped | S8: VQA | T8: SENT | U8: DONE | V8: DONE | W8: DONE
F9: TOTAL | J9: =SUM(J5:J8) -> 168 | K9: =SUM(K8:K8) -> 42 | L9: =SUM(L8:L8) -> 42 | M9: =SUM(M8:M8) -> 0 | N9: =SUM(N8:N8) -> 42 | O9: =SUM(O8:O8) -> 0 | P9: =SUM(P5:P8) -> 168 | Q9: =SUM(Q5:Q8) -> 13 | R9: Shipped
B11: Line | C11: PLANT CODE | D11: LINE NO | E11: CON | F11: DESTINATION | G11: PO NO | H11: COLOR | I11: MATERIAL NO | J11: QTY | K11: CUT QTY | L11: Send to Wash / Dye | M11: Balance to Send | N11: Wash / Dye Received | O11: Balance to receive | P11: PACK/SHIP QTY | Q11: CTNS | R11: STATUS | S11: FI to be done by | T11: ASN | U11: WEIGHT | V11: WFX | W11: OCR | X11: BOOKING NO | Y11: DO | Z11: INV NO
B12: 6 | C12: TO40 | D12: 10 | E12: PRLS/25/12211 | F12: CANADA | G12: 4702053662 | H12: CARMEL PINK | I12: 710967632006 | J12: 264 | K12: =P12 -> 264 | L12: =K12 -> 264 | M12: 0 | N12: =L12 -> 264 | O12: 0 | P12: 264 | Q12: 15 | R12: Shipped | S12: VQA | T12: SENT | U12: DONE | V12: DONE | W12: DONE | X12: IBKG0000213024
F13: TOTAL | J13: =SUM(J12) -> 264 | K13: =SUM(K12:K12) -> 264 | L13: =SUM(L12:L12) -> 264 | M13: =SUM(M12:M12) -> 0 | N13: =SUM(N12:N12) -> 264 | O13: =SUM(O12:O12) -> 0 | P13: =SUM(P12) -> 264 | Q13: =SUM(Q12) -> 15 | R13: Shipped
B15: Line | C15: PLANT CODE | D15: LINE NO | E15: CON | F15: DESTINATION | G15: PO NO | H15: COLOR | I15: MATERIAL NO | J15: QTY | K15: CUT QTY | L15: Send to Wash / Dye | M15: Balance to Send | N15: Wash / Dye Received | O15: Balance to receive | P15: PACK/SHIP QTY | Q15: CTNS | R15: STATUS | S15: FI to be done by | T15: ASN | U15: WEIGHT | V15: WFX | W15: OCR | X15: BOOKING NO | Y15: DO | Z15: INV NO
B16: 5 | C16: TO40 | D16: 10 | E16: PRLS/25/12334 | F16: CANADA | G16: 4702048643 | H16: 5463 WHITE/YELLOW MULTI | I16: 710B23578001 | J16: 224 | K16: 224 | L16: =K16-M16 -> 224 | N16: =L16-O16 -> 224 | P16: 224 | Q16: 4 | R16: Shipped | S16: VQA | T16: SENT | U16: DONE | V16: DONE | X16: IBKG0000213020
F17: TOTAL | J17: =SUM(J16) -> 224 | K17: =SUM(K16:K16) -> 224 | L17: =SUM(L16:L16) -> 224 | M17: =SUM(M16:M16) -> 0 | N17: =SUM(N16:N16) -> 224 | O17: =SUM(O16:O16) -> 0 | P17: =SUM(P16) -> 224 | Q17: =SUM(Q16) -> 4 | R17: Shipped
B19: Line | C19: PLANT CODE | D19: LINE NO | E19: CON | F19: DESTINATION | G19: PO NO | H19: COLOR | I19: MATERIAL NO | J19: QTY | K19: CUT QTY | L19: Send to Wash / Dye | M19: Balance to Send | N19: Wash / Dye Received | O19: Balance to receive | P19: PACK/SHIP QTY | Q19: CTNS | R19: STATUS | S19: FI to be done by | T19: ASN | U19: WEIGHT | V19: WFX | W19: OCR | X19: BOOKING NO | Y19: DO | Z19: INV NO
B20: 6 | C20: CA10 | D20: 10 | E20: PRLS/25/12139 | F20: ITALY | G20: 4702043041 | H20: 7188A WHITE BLUE | I20: 710B15594004 | J20: 2100 | K20: =P20 -> 2161 | L20: =K20 -> 2161 | M20: 0 | N20: =L20 -> 2161 | O20: 0 | P20: 2161 | Q20: 125 | R20: Shipped | S20: VQA | T20: SENT | U20: DONE | V20: DONE | W20: DONE | X20: IBKG0000212611
