Workbook

Sheet HOME
B2: HUGO BOSS
B3: PACKING LIST MANAGEMENT SYSTEM | v1.0.0
B5: Current User: | C5: Packing Manager | E5: Date: | F5: =TEXT(TODAY(),"DD.MM.YYYY") -> 03.07.2026 | H5: Version: | I5: 1.0.0
B7: TOTAL ACTIVE POs | D7: TOTAL PACKED | F7: TOTAL CARTONS | H7: COMPLETION % | J7: STATUS
B8: 2 | D8: 0 | F8: 0 | H8: 0% | J8: READY
B9: Packing Progress
B10: ░░░░░░░░░░░░░░░░░░░░░░░░░░░░░░░░░░░░░░ 0% Complete
B12: QUICK ACTIONS
B14: 📥 IMPORT PO | E14: 📋 CREATE PACKING LIST | H14: 📦 AUTO ALLOCATE
B16: ✔ VALIDATE | E16: 📊 DASHBOARD | H16: 📈 GENERATE SUMMARY
B18: 🖨 EXPORT PDF | E18: 💾 EXPORT XLSX | H18: 🗑 CLEAR DATA
B20: ⚙ SETTINGS
B22: WORKBOOK SHEETS
B23: 🏠 HOME | C23: Landing page | E23: 📄 PO_MASTER | F23: Purchase Orders DB | H23: 📋 PACKING_LIST | I23: Main working sheet
B24: 📦 CARTON_ALLOCATION | C24: Auto distribution | E24: ✂ CUT_SHEET | F24: Production compare | H24: 🗂 MASTER_DATA | I24: Lookup tables
B25: ⚙ SETTINGS | C25: Configuration | E25: 📊 DASHBOARD | F25: KPIs & Charts | H25: 📤 EXPORT | I25: Print/PDF/XLSX
B27: © 2026 Hugo Boss Packing List System • Laguna India Private Limited • Sample POs: 4901873568 · 4901893255

Sheet PO_MASTER
A1: PO MASTER — Purchase Order Database
A2: All active purchase orders • Never overwrite • Duplicate detection enabled • Supports unlimited POs
A4: # | B4: PO Number | C4: Season | D4: Customer | E4: Brand | F4: Division | G4: Factory | H4: Style | I4: Form | J4: Form Name | K4: Quality | L4: Color Code | M4: Color Description | N4: Size | O4: Ordered Qty | P4: Delivery Date | Q4: Destination | R4: Unit Price | S4: Currency | T4: Status
A5: 1 | B5: 4901873568 | C5: W26WI | D5: HUGO BOSS Ticino SA | E5: BOSS | F5: Black | G5: LAGUNA INDIA PVT LTD | H5: 50473265 | I5: 251087 | J5: H-JOE-kent-C1-214 | K5: 10219212 | L5: 1 | M5: Black | N5: 37 | O5: 50 | P5: 22.07.2026 | Q5: DC FPG Filderstadt Germany | R5: 13.3 | S5: USD | T5: Active
A6: 2 | B6: 4901873568 | C6: W26WI | D6: HUGO BOSS Ticino SA | E6: BOSS | F6: Black | G6: LAGUNA INDIA PVT LTD | H6: 50473265 | I6: 251087 | J6: H-JOE-kent-C1-214 | K6: 10219212 | L6: 1 | M6: Black | N6: 38 | O6: 210 | P6: 22.07.2026 | Q6: DC FPG Filderstadt Germany | R6: 13.3 | S6: USD | T6: Active
A7: 3 | B7: 4901873568 | C7: W26WI | D7: HUGO BOSS Ticino SA | E7: BOSS | F7: Black | G7: LAGUNA INDIA PVT LTD | H7: 50473265 | I7: 251087 | J7: H-JOE-kent-C1-214 | K7: 10219212 | L7: 1 | M7: Black | N7: 39 | O7: 524 | P7: 22.07.2026 | Q7: DC FPG Filderstadt Germany | R7: 13.3 | S7: USD | T7: Active
A8: 4 | B8: 4901873568 | C8: W26WI | D8: HUGO BOSS Ticino SA | E8: BOSS | F8: Black | G8: LAGUNA INDIA PVT LTD | H8: 50473265 | I8: 251087 | J8: H-JOE-kent-C1-214 | K8: 10219212 | L8: 1 | M8: Black | N8: 40 | O8: 597 | P8: 22.07.2026 | Q8: DC FPG Filderstadt Germany | R8: 13.3 | S8: USD | T8: Active
A9: 5 | B9: 4901873568 | C9: W26WI | D9: HUGO BOSS Ticino SA | E9: BOSS | F9: Black | G9: LAGUNA INDIA PVT LTD | H9: 50473265 | I9: 251087 | J9: H-JOE-kent-C1-214 | K9: 10219212 | L9: 1 | M9: Black | N9: 41 | O9: 443 | P9: 22.07.2026 | Q9: DC FPG Filderstadt Germany | R9: 13.3 | S9: USD | T9: Active
A10: 6 | B10: 4901873568 | C10: W26WI | D10: HUGO BOSS Ticino SA | E10: BOSS | F10: Black | G10: LAGUNA INDIA PVT LTD | H10: 50473265 | I10: 251087 | J10: H-JOE-kent-C1-214 | K10: 10219212 | L10: 1 | M10: Black | N10: 42 | O10: 608 | P10: 22.07.2026 | Q10: DC FPG Filderstadt Germany | R10: 13.3 | S10: USD | T10: Active
A11: 7 | B11: 4901873568 | C11: W26WI | D11: HUGO BOSS Ticino SA | E11: BOSS | F11: Black | G11: LAGUNA INDIA PVT LTD | H11: 50473265 | I11: 251087 | J11: H-JOE-kent-C1-214 | K11: 10219212 | L11: 1 | M11: Black | N11: 43 | O11: 562 | P11: 22.07.2026 | Q11: DC FPG Filderstadt Germany | R11: 13.3 | S11: USD | T11: Active
A12: 8 | B12: 4901873568 | C12: W26WI | D12: HUGO BOSS Ticino SA | E12: BOSS | F12: Black | G12: LAGUNA INDIA PVT LTD | H12: 50473265 | I12: 251087 | J12: H-JOE-kent-C1-214 | K12: 10219212 | L12: 1 | M12: Black | N12: 44 | O12: 482 | P12: 22.07.2026 | Q12: DC FPG Filderstadt Germany | R12: 13.3 | S12: USD | T12: Active
A13: 9 | B13: 4901873568 | C13: W26WI | D13: HUGO BOSS Ticino SA | E13: BOSS | F13: Black | G13: LAGUNA INDIA PVT LTD | H13: 50473265 | I13: 251087 | J13: H-JOE-kent-C1-214 | K13: 10219212 | L13: 1 | M13: Black | N13: 45 | O13: 303 | P13: 22.07.2026 | Q13: DC FPG Filderstadt Germany | R13: 13.3 | S13: USD | T13: Active
A14: 10 | B14: 4901873568 | C14: W26WI | D14: HUGO BOSS Ticino SA | E14: BOSS | F14: Black | G14: LAGUNA INDIA PVT LTD | H14: 50473265 | I14: 251087 | J14: H-JOE-kent-C1-214 | K14: 10219212 | L14: 1 | M14: Black | N14: 46 | O14: 280 | P14: 22.07.2026 | Q14: DC FPG Filderstadt Germany | R14: 13.3 | S14: USD | T14: Active
A15: 11 | B15: 4901873568 | C15: W26WI | D15: HUGO BOSS Ticino SA | E15: BOSS | F15: Black | G15: LAGUNA INDIA PVT LTD | H15: 50473265 | I15: 251087 | J15: H-JOE-kent-C1-214 | K15: 10219212 | L15: 1 | M15: Black | N15: 47 | O15: 1 | P15: 22.07.2026 | Q15: DC FPG Filderstadt Germany | R15: 13.3 | S15: USD | T15: Active
A16: 12 | B16: 4901873568 | C16: W26WI | D16: HUGO BOSS Ticino SA | E16: BOSS | F16: Black | G16: LAGUNA INDIA PVT LTD | H16: 50473265 | I16: 251087 | J16: H-JOE-kent-C1-214 | K16: 10219212 | L16: 1 | M16: Black | N16: 48 | O16: 12 | P16: 22.07.2026 | Q16: DC FPG Filderstadt Germany | R16: 13.3 | S16: USD | T16: Active
... A18: 14 | B18: 4901873568 | C18: W26WI | D18: HUGO BOSS Ticino SA | E18: BOSS | F18: Black | G18: LAGUNA INDIA PVT LTD | H18: 50473265 | I18: 251087 | J18: H-JOE-kent-C1-214 | K18: 10219212 | L18: 1 | M18: Black | N18: 50 | O18: 1 | P18: 22.07.2026 | Q18: DC FPG Filderstadt Germany | R18: 13.3 | S18: USD | T18: Active
A19: 15 | B19: 4901873568 | C19: W26WI | D19: HUGO BOSS Ticino SA | E19: BOSS | F19: Black | G19: LAGUNA INDIA PVT LTD | H19: 50473265 | I19: 251087 | J19: H-JOE-kent-C1-214 | K19: 10219212 | L19: 1 | M19: Black | N19: 42L | O19: 10 | P19: 22.07.2026 | Q19: DC FPG Filderstadt Germany | R19: 13.3 | S19: USD | T19: Active
A20: 16 | B20: 4901873568 | C20: W26WI | D20: HUGO BOSS Ticino SA | E20: BOSS | F20: Black | G20: LAGUNA INDIA PVT LTD | H20: 50473265 | I20: 251087 | J20: H-JOE-kent-C1-214 | K20: 10219212 | L20: 1 | M20: Black | N20: 43L | O20: 43 | P20: 22.07.2026 | Q20: DC FPG Filderstadt Germany | R20: 13.3 | S20: USD | T20: Active
A21: 17 | B21: 4901873568 | C21: W26WI | D21: HUGO BOSS Ticino SA | E21: BOSS | F21: Black | G21: LAGUNA INDIA PVT LTD | H21: 50473265 | I21: 251087 | J21: H-JOE-kent-C1-214 | K21: 10219212 | L21: 1 | M21: Black | N21: 44L | O21: 35 | P21: 22.07.2026 | Q21: DC FPG Filderstadt Germany | R21: 13.3 | S21: USD | T21: Active
A22: 18 | B22: 4901873568 | C22: W26WI | D22: HUGO BOSS Ticino SA | E22: BOSS | F22: Black | G22: LAGUNA INDIA PVT LTD | H22: 50473265 | I22: 251087 | J22: H-JOE-kent-C1-214 | K22: 10219212 | L22: 1 | M22: Black | N22: 45L | O22: 30 | P22: 22.07.2026 | Q22: DC FPG Filderstadt Germany | R22: 13.3 | S22: USD | T22: Active
A23: 19 | B23: 4901873568 | C23: W26WI | D23: HUGO BOSS Ticino SA | E23: BOSS | F23: Black | G23: LAGUNA INDIA PVT LTD | H23: 50473265 | I23: 251087 | J23: H-JOE-kent-C1-214 | K23: 10219212 | L23: 100 | M23: White | N23: 37 | O23: 58 | P23: 22.07.2026 | Q23: DC FPG Filderstadt Germany | R23: 13.3 | S23: USD | T23: Active
A24: 20 | B24: 4901873568 | C24: W26WI | D24: HUGO BOSS Ticino SA | E24: BOSS | F24: Black | G24: LAGUNA INDIA PVT LTD | H24: 50473265 | I24: 251087 | J24: H-JOE-kent-C1-214 | K24: 10219212 | L24: 100 | M24: White | N24: 38 | O24: 410 | P24: 22.07.2026 | Q24: DC FPG Filderstadt Germany | R24: 13.3 | S24: USD | T24: Active
A25: 21 | B25: 4901873568 | C25: W26WI | D25: HUGO BOSS Ticino SA | E25: BOSS | F25: Black | G25: LAGUNA INDIA PVT LTD | H25: 50473265 | I25: 251087 | J25: H-JOE-kent-C1-214 | K25: 10219212 | L25: 100 | M25: White | N25: 39 | O25: 606 | P25: 22.07.2026 | Q25: DC FPG Filderstadt Germany | R25: 13.3 | S25: USD | T25: Active
A26: 22 | B26: 4901873568 | C26: W26WI | D26: HUGO BOSS Ticino SA | E26: BOSS | F26: Black | G26: LAGUNA INDIA PVT LTD | H26: 50473265 | I26: 251087 | J26: H-JOE-kent-C1-214 | K26: 10219212 | L26: 100 | M26: White | N26: 40 | O26: 1005 | P26: 22.07.2026 | Q26: DC FPG Filderstadt Germany | R26: 13.3 | S26: USD | T26: Active
A27: 23 | B27: 4901873568 | C27: W26WI | D27: HUGO BOSS Ticino SA | E27: BOSS | F27: Black | G27: LAGUNA INDIA PVT LTD | H27: 50473265 | I27: 251087 | J27: H-JOE-kent-C1-214 | K27: 10219212 | L27: 100 | M27: White | N27: 41 | O27: 885 | P27: 22.07.2026 | Q27: DC FPG Filderstadt Germany | R27: 13.3 | S27: USD | T27: Active
A28: 24 | B28: 4901873568 | C28: W26WI | D28: HUGO BOSS Ticino SA | E28: BOSS | F28: Black | G28: LAGUNA INDIA PVT LTD | H28: 50473265 | I28: 251087 | J28: H-JOE-kent-C1-214 | K28: 10219212 | L28: 100 | M28: White | N28: 42 | O28: 994 | P28: 22.07.2026 | Q28: DC FPG Filderstadt Germany | R28: 13.3 | S28: USD | T28: Active
A29: 25 | B29: 4901873568 | C29: W26WI | D29: HUGO BOSS Ticino SA | E29: BOSS | F29: Black | G29: LAGUNA INDIA PVT LTD | H29: 50473265 | I29: 251087 | J29: H-JOE-kent-C1-214 | K29: 10219212 | L29: 100 | M29: White | N29: 43 | O29: 797 | P29: 22.07.2026 | Q29: DC FPG Filderstadt Germany | R29: 13.3 | S29: USD | T29: Active
A30: 26 | B30: 4901873568 | C30: W26WI | D30: HUGO BOSS Ticino SA | E30: BOSS | F30: Black | G30: LAGUNA INDIA PVT LTD | H30: 50473265 | I30: 251087 | J30: H-JOE-kent-C1-214 | K30: 10219212 | L30: 100 | M30: White | N30: 44 | O30: 603 | P30: 22.07.2026 | Q30: DC FPG Filderstadt Germany | R30: 13.3 | S30: USD | T30: Active
A31: 27 | B31: 4901873568 | C31: W26WI | D31: HUGO BOSS Ticino SA | E31: BOSS | F31: Black | G31: LAGUNA INDIA PVT LTD | H31: 50473265 | I31: 251087 | J31: H-JOE-kent-C1-214 | K31: 10219212 | L31: 100 | M31: White | N31: 45 | O31: 342 | P31: 22.07.2026 | Q31: DC FPG Filderstadt Germany | R31: 13.3 | S31: USD | T31: Active
A32: 28 | B32: 4901873568 | C32: W26WI | D32: HUGO BOSS Ticino SA | E32: BOSS | F32: Black | G32: LAGUNA INDIA PVT LTD | H32: 50473265 | I32: 251087 | J32: H-JOE-kent-C1-214 | K32: 10219212 | L32: 100 | M32: White | N32: 46 | O32: 378 | P32: 22.07.2026 | Q32: DC FPG Filderstadt Germany | R32: 13.3 | S32: USD | T32: Active
A33: 29 | B33: 4901873568 | C33: W26WI | D33: HUGO BOSS Ticino SA | E33: BOSS | F33: Black | G33: LAGUNA INDIA PVT LTD | H33: 50473265 | I33: 251087 | J33: H-JOE-kent-C1-214 | K33: 10219212 | L33: 100 | M33: White | N33: 48 | O33: 6 | P33: 22.07.2026 | Q33: DC FPG Filderstadt Germany | R33: 13.3 | S33: USD | T33: Active
A34: 30 | B34: 4901873568 | C34: W26WI | D34: HUGO BOSS Ticino SA | E34: BOSS | F34: Black | G34: LAGUNA INDIA PVT LTD | H34: 50473265 | I34: 251087 | J34: H-JOE-kent-C1-214 | K34: 10219212 | L34: 404 | M34: Dark Blue | N34: 37 | O34: 18 | P34: 22.07.2026 | Q34: DC FPG Filderstadt Germany | R34: 13.3 | S34: USD | T34: Active
... A43: 39 | B43: 4901873568 | C43: W26WI | D43: HUGO BOSS Ticino SA | E43: BOSS | F43: Black | G43: LAGUNA INDIA PVT LTD | H43: 50473265 | I43: 251087 | J43: H-JOE-kent-C1-214 | K43: 10219212 | L43: 404 | M43: Dark Blue | N43: 46 | O43: 113 | P43: 22.07.2026 | Q43: DC FPG Filderstadt Germany | R43: 13.3 | S43: USD | T43: Active
A44: 40 | B44: 4901873568 | C44: W26WI | D44: HUGO BOSS Ticino SA | E44: BOSS | F44: Black | G44: LAGUNA INDIA PVT LTD | H44: 50473265 | I44: 251087 | J44: H-JOE-kent-C1-214 | K44: 10219212 | L44: 404 | M44: Dark Blue | N44: 43L | O44: 27 | P44: 22.07.2026 | Q44: DC FPG Filderstadt Germany | R44: 13.3 | S44: USD | T44: Active
A45: 41 | B45: 4901873568 | C45: W26WI | D45: HUGO BOSS Ticino SA | E45: BOSS | F45: Black | G45: LAGUNA INDIA PVT LTD | H45: 50473265 | I45: 251087 | J45: H-JOE-kent-C1-214 | K45: 10219212 | L45: 404 | M45: Dark Blue | N45: 44L | O45: 38 | P45: 22.07.2026 | Q45: DC FPG Filderstadt Germany | R45: 13.3 | S45: USD | T45: Active
A46: 42 | B46: 4901873568 | C46: W26WI | D46: HUGO BOSS Ticino SA | E46: BOSS | F46: Black | G46: LAGUNA INDIA PVT LTD | H46: 50473265 | I46: 251087 | J46: H-JOE-kent-C1-214 | K46: 10219212 | L46: 404 | M46: Dark Blue | N46: 45L | O46: 15 | P46: 22.07.2026 | Q46: DC FPG Filderstadt Germany | R46: 13.3 | S46: USD | T46: Active
A47: 43 | B47: 4901873568 | C47: W26WI | D47: HUGO BOSS Ticino SA | E47: BOSS | F47: Black | G47: LAGUNA INDIA PVT LTD | H47: 50473265 | I47: 251087 | J47: H-JOE-kent-C1-214 | K47: 10219212 | L47: 452 | M47: Light Blue | N47: 37 | O47: 13 | P47: 22.07.2026 | Q47: DC FPG Filderstadt Germany | R47: 13.3 | S47: USD | T47: Active
A48: 44 | B48: 4901873568 | C48: W26WI | D48: HUGO BOSS Ticino SA | E48: BOSS | F48: Black | G48: LAGUNA INDIA PVT LTD | H48: 50473265 | I48: 251087 | J48: H-JOE-kent-C1-214 | K48: 10219212 | L48: 452 | M48: Light Blue | N48: 38 | O48: 109 | P48: 22.07.2026 | Q48: DC FPG Filderstadt Germany | R48: 13.3 | S48: USD | T48: Active
A49: 45 | B49: 4901873568 | C49: W26WI | D49: HUGO BOSS Ticino SA | E49: BOSS | F49: Black | G49: LAGUNA INDIA PVT LTD | H49: 50473265 | I49: 251087 | J49: H-JOE-kent-C1-214 | K49: 10219212 | L49: 452 | M49: Light Blue | N49: 39 | O49: 273 | P49: 22.07.2026 | Q49: DC FPG Filderstadt Germany | R49: 13.3 | S49: USD | T49: Active
A50: 46 | B50: 4901873568 | C50: W26WI | D50: HUGO BOSS Ticino SA | E50: BOSS | F50: Black | G50: LAGUNA INDIA PVT LTD | H50: 50473265 | I50: 251087 | J50: H-JOE-kent-C1-214 | K50: 10219212 | L50: 452 | M50: Light Blue | N50: 40 | O50: 393 | P50: 22.07.2026 | Q50: DC FPG Filderstadt Germany | R50: 13.3 | S50: USD | T50: Active
...

Sheet PACKING_LIST
A1: HUGO BOSS
A2: PACKING LIST
B4: PO Number: | D4: 4901873568 | G4: Style: | I4: 50473265 | L4: Form: | N4: 251087 | Q4: Form Name: | S4: H-JOE-kent-C1-214 | W4: Season: | Y4: W26WI | AC4: Packing List No: PL-4901873568-001
B5: Invoice No: | D5: INV-4901873568-001 | G5: Shipment: | I5: SCC Sea freight | L5: Container: | N5: MSKU-1234567 | Q5: Factory: | S5: LAGUNA INDIA PVT LTD | W5: Vendor No: | Y5: 6094373 | AC5: Terms: FOB IN_MAA
B6: Customer: | D6: HUGO BOSS Ticino SA | G6: Destination: | I6: DC FPG Filderstadt, Hugo Boss Str. 1-7, 70794 Filderstadt, Germany | Q6: Delivery Date: | S6: 22.07.2026 | W6: Quality: | Y6: 10219212 | AC6: Payment: 100 days net
B7: Brand: | D7: BOSS | G7: Division: | I7: Men Black | L7: Category: | N7: Shirts | Q7: Unit Price: | S7: USD 13.30 / PC | W7: Currency: | Y7: USD | AC7: Date: 02.07.2026
B9: CARTON DETAILS • Dynamic Size Columns (Numeric 37–50 + Long 42L–45L)
B10: Ctn No | C10: Color | D10: Size Range | E10: SIZE DISTRIBUTION (pcs per size) | W10: Total Qty | X10: WEIGHT (kg) | AA10: DIMENSIONS (cm) | AD10: CBM | AE10: Remarks
E11: 37 | F11: 38 | G11: 39 | H11: 40 | I11: 41 | J11: 42 | K11: 43 | L11: 44 | M11: 45 | N11: 46 | O11: 47 | P11: 48 | Q11: 49 | R11: 50 | S11: 42L | T11: 43L | U11: 44L | V11: 45L | X11: Net | Y11: Gross | Z11: Carton | AA11: L | AB11: W | AC11: H
B12: 1 | C12: 1 | D12: 37-40 Mix | E12: 1 | F12: 3 | G12: 5 | H12: 5 | W12: =SUM(E12:V12) -> 14 | X12: =W12*0.28 -> 3.92 | Y12: =X12+Z12 -> 5.12 | Z12: 1.2 | AA12: 50 | AB12: 40 | AC12: 30 | AD12: =AA12*AB12*AC12/1000000 -> 0.06 | AE12: Std
B13: 2 | C13: 1 | D13: 40-42 Mix | H13: 2 | I13: 4 | J13: 8 | W13: =SUM(E13:V13) -> 14 | X13: =W13*0.28 -> 3.92 | Y13: =X13+Z13 -> 5.12 | Z13: 1.2 | AA13: 50 | AB13: 40 | AC13: 30 | AD13: =AA13*AB13*AC13/1000000 -> 0.06 | AE13: Std
B14: 3 | C14: 1 | D14: 42-44 Mix | J14: 3 | K14: 6 | L14: 5 | W14: =SUM(E14:V14) -> 14 | X14: =W14*0.28 -> 3.92 | Y14: =X14+Z14 -> 5.12 | Z14: 1.2 | AA14: 50 | AB14: 40 | AC14: 30 | AD14: =AA14*AB14*AC14/1000000 -> 0.06 | AE14: Std
B15: 4 | C15: 1 | D15: 44-46+L Mix | L15: 3 | M15: 4 | N15: 4 | S15: 1 | T15: 2 | W15: =SUM(E15:V15) -> 14 | X15: =W15*0.28 -> 3.92 | Y15: =X15+Z15 -> 5.12 | Z15: 1.2 | AA15: 50 | AB15: 40 | AC15: 30 | AD15: =AA15*AB15*AC15/1000000 -> 0.06 | AE15: Std
B16: 5 | C16: 100 | D16: 37-40 Mix | E16: 1 | F16: 4 | G16: 5 | H16: 4 | W16: =SUM(E16:V16) -> 14 | X16: =W16*0.28 -> 3.92 | Y16: =X16+Z16 -> 5.12 | Z16: 1.2 | AA16: 50 | AB16: 40 | AC16: 30 | AD16: =AA16*AB16*AC16/1000000 -> 0.06 | AE16: Std
B17: 6 | C17: 100 | D17: 40-42 Mix | H17: 3 | I17: 5 | J17: 6 | W17: =SUM(E17:V17) -> 14 | X17: =W17*0.28 -> 3.92 | Y17: =X17+Z17 -> 5.12 | Z17: 1.2 | AA17: 50 | AB17: 40 | AC17: 30 | AD17: =AA17*AB17*AC17/1000000 -> 0.06 | AE17: Std
B18: 7 | C18: 404 | D18: 39-42 Mix | G18: 1 | H18: 3 | I18: 4 | J18: 6 | W18: =SUM(E18:V18) -> 14 | X18: =W18*0.28 -> 3.92 | Y18: =X18+Z18 -> 5.12 | Z18: 1.2 | AA18: 50 | AB18: 40 | AC18: 30 | AD18: =AA18*AB18*AC18/1000000 -> 0.06 | AE18: Std
B19: 8 | C19: 404 | D19: 42-44 Mix | J19: 4 | K19: 5 | L19: 5 | W19: =SUM(E19:V19) -> 14 | X19: =W19*0.28 -> 3.92 | Y19: =X19+Z19 -> 5.12 | Z19: 1.2 | AA19: 50 | AB19: 40 | AC19: 30 | AD19: =AA19*AB19*AC19/1000000 -> 0.06 | AE19: Std
B20: 9 | C20: 452 | D20: 40-42 Mix | H20: 3 | I20: 5 | J20: 6 | W20: =SUM(E20:V20) -> 14 | X20: =W20*0.28 -> 3.92 | Y20: =X20+Z20 -> 5.12 | Z20: 1.2 | AA20: 50 | AB20: 40 | AC20: 30 | AD20: =AA20*AB20*AC20/1000000 -> 0.06 | AE20: Std
B21: 10 | C21: 452 | D21: 42-44 Mix | J21: 4 | K21: 5 | L21: 5 | W21: =SUM(E21:V21) -> 14 | X21: =W21*0.28 -> 3.92 | Y21: =X21+Z21 -> 5.12 | Z21: 1.2 | AA21: 50 | AB21: 40 | AC21: 30 | AD21: =AA21*AB21*AC21/1000000 -> 0.06 | AE21: Std
B22: TOTAL (10 CARTONS SAMPLE) | E22: =SUM(E12:E21) -> 2 | F22: =SUM(F12:F21) -> 7 | G22: =SUM(G12:G21) -> 11 | H22: =SUM(H12:H21) -> 20 | I22: =SUM(I12:I21) -> 18 | J22: =SUM(J12:J21) -> 37 | K22: =SUM(K12:K21) -> 16 | L22: =SUM(L12:L21) -> 18 | ... Z22: =SUM(Z12:Z21) -> 12 | AD22: =SUM(AD12:AD21) -> 0.6
B24: PACKING SUMMARY
B25: PO Number | D25: Style / Form Name | H25: Total Ordered | K25: Packed (Sample) | N25: Remaining | Q25: Cartons Used | T25: Total Net (kg) | W25: Total Gross (kg) | Z25: Total CBM | AC25: Completion
B26: 4901873568 | D26: 50473265 / H-JOE-kent-C1-214 | H26: =SUMIFS(PO_MASTER!O:O,PO_MASTER!B:B,4901873568) -> 16945 | K26: {=W22} -> 140 | N26: =H26-K26 -> 16805 | Q26: 10 | T26: {=X22} -> 39.2 | W26: {=Y22} -> 51.2 | Z26: {=AD22} -> 0.6 | AC26: =TEXT(K26/H26,"0.0%") -> 0.8%
B28: This packing list is generated automatically from PO_MASTER. Sizes columns are dynamically populated based on PO requirements. Sample shows first 10 cartons.
B30: Prepared by: _______________ | G30: Checked by: _______________ | L30: Quality: _______________ | Q30: Factory Sign: _______________ | V30: Date: ___/___/2026

Sheet CARTON_ALLOCATION
A1: CARTON ALLOCATION — Automatic Distribution Engine
A2: Automatically distributes garments into cartons maintaining size distribution
B4: ALGORITHM CONFIGURATION
B5: Carton Capacity (pcs): | D5: 14 | E5: (Options: 10, 12, 14, 15, 18, 20) | G5: Default Weight (g/pc): | I5: 300 | J5: grams per piece
B6: Carton Tare (g): | D6: 1200 | E6: empty carton weight | G6: Tolerance (%): | I6: 2 | J6: accepted variance %
B8: ALGORITHM: FullCartons = INT(Qty / Capacity) • Remainder = MOD(Qty, Capacity) • Total = FullCartons + (Remainder > 0 ? 1 : 0)
B10: ALLOCATION TABLE — Live from PO_MASTER (each PO Color+Size)
B11: PO# | C11: Color | D11: Size | E11: Ordered | F11: Capacity | G11: Full Ctns | H11: Remainder | I11: Total Ctns | J11: Last Ctn Pcs | K11: Efficiency % | L11: Distribution | M11: Ctn 1 | N11: Ctn 2 | O11: Ctn 3 | P11: Ctn 4 | Q11: Ctn 5+
B12: {=PO_MASTER!B8} -> 4901873568 | C12: =TEXT(PO_MASTER!L8,"000") -> 001 | D12: {=PO_MASTER!N8} -> 40 | E12: {=PO_MASTER!O8} -> 597 | F12: {=$D$5} -> 14 | G12: =INT(E12/F12) -> 42 | H12: =MOD(E12,F12) -> 9 | I12: =G12+IF(H12>0,1,0) -> 43 | J12: {=IF(H12>0,H12,F12)} -> 9 | K12: =E12/(I12*F12) -> 0.99169435 | L12: =G12&" × "&F12&" + "&IF(H12>0,"1 × "&H12,"0") -> 42 × 14 + 1 × 9 | M12: =MIN(E12,F12) -> 14 | N12: =IF(E12>F12,MIN(E12-F12,F12),0) -> 14 | O12: =IF(E12>2*F12,MIN(E12-2*F12,F12),0) -> 14 | P12: =IF(E12>3*F12,MIN(E12-3*F12,F12),0) -> 14 | Q12: =MAX(0,E12-4*F12) -> 541
B13: {=PO_MASTER!B11} -> 4901873568 | C13: =TEXT(PO_MASTER!L11,"000") -> 001 | D13: {=PO_MASTER!N11} -> 43 | E13: {=PO_MASTER!O11} -> 562 | F13: {=$D$5} -> 14 | G13: =INT(E13/F13) -> 40 | H13: =MOD(E13,F13) -> 2 | I13: =G13+IF(H13>0,1,0) -> 41 | J13: {=IF(H13>0,H13,F13)} -> 2 | K13: =E13/(I13*F13) -> 0.97909408 | L13: =G13&" × "&F13&" + "&IF(H13>0,"1 × "&H13,"0") -> 40 × 14 + 1 × 2 | M13: =MIN(E13,F13) -> 14 | N13: =IF(E13>F13,MIN(E13-F13,F13),0) -> 14 | O13: =IF(E13>2*F13,MIN(E13-2*F13,F13),0) -> 14 | P13: =IF(E13>3*F13,MIN(E13-3*F13,F13),0) -> 14 | Q13: =MAX(0,E13-4*F13) -> 506
B14: {=PO_MASTER!B14} -> 4901873568 | C14: =TEXT(PO_MASTER!L14,"000") -> 001 | D14: {=PO_MASTER!N14} -> 46 | E14: {=PO_MASTER!O14} -> 280 | F14: {=$D$5} -> 14 | G14: =INT(E14/F14) -> 20 | H14: =MOD(E14,F14) -> 0 | I14: =G14+IF(H14>0,1,0) -> 20 | J14: {=IF(H14>0,H14,F14)} -> 14 | K14: =E14/(I14*F14) -> 1 | L14: =G14&" × "&F14&" + "&IF(H14>0,"1 × "&H14,"0") -> 20 × 14 + 0 | M14: =MIN(E14,F14) -> 14 | N14: =IF(E14>F14,MIN(E14-F14,F14),0) -> 14 | O14: =IF(E14>2*F14,MIN(E14-2*F14,F14),0) -> 14 | P14: =IF(E14>3*F14,MIN(E14-3*F14,F14),0) -> 14 | Q14: =MAX(0,E14-4*F14) -> 224
B15: {=PO_MASTER!B15} -> 4901873568 | C15: =TEXT(PO_MASTER!L15,"000") -> 001 | D15: {=PO_MASTER!N15} -> 47 | E15: {=PO_MASTER!O15} -> 1 | F15: {=$D$5} -> 14 | G15: =INT(E15/F15) -> 0 | H15: =MOD(E15,F15) -> 1 | I15: =G15+IF(H15>0,1,0) -> 1 | J15: {=IF(H15>0,H15,F15)} -> 1 | K15: =E15/(I15*F15) -> 0.071428571 | L15: =G15&" × "&F15&" + "&IF(H15>0,"1 × "&H15,"0") -> 0 × 14 + 1 × 1 | M15: =MIN(E15,F15) -> 1 | N15: =IF(E15>F15,MIN(E15-F15,F15),0) -> 0 | O15: =IF(E15>2*F15,MIN(E15-2*F15,F15),0) -> 0 | P15: =IF(E15>3*F15,MIN(E15-3*F15,F15),0) -> 0 | Q15: =MAX(0,E15-4*F15) -> 0
B16: {=PO_MASTER!B22} -> 4901873568 | C16: =TEXT(PO_MASTER!L22,"000") -> 001 | D16: {=PO_MASTER!N22} -> 45L | E16: {=PO_MASTER!O22} -> 30 | F16: {=$D$5} -> 14 | G16: =INT(E16/F16) -> 2 | H16: =MOD(E16,F16) -> 2 | I16: =G16+IF(H16>0,1,0) -> 3 | J16: {=IF(H16>0,H16,F16)} -> 2 | K16: =E16/(I16*F16) -> 0.71428571 | L16: =G16&" × "&F16&" + "&IF(H16>0,"1 × "&H16,"0") -> 2 × 14 + 1 × 2 | M16: =MIN(E16,F16) -> 14 | N16: =IF(E16>F16,MIN(E16-F16,F16),0) -> 14 | O16: =IF(E16>2*F16,MIN(E16-2*F16,F16),0) -> 2 | P16: =IF(E16>3*F16,MIN(E16-3*F16,F16),0) -> 0 | Q16: =MAX(0,E16-4*F16) -> 0
B17: {=PO_MASTER!B26} -> 4901873568 | C17: =TEXT(PO_MASTER!L26,"000") -> 100 | D17: {=PO_MASTER!N26} -> 40 | E17: {=PO_MASTER!O26} -> 1005 | F17: {=$D$5} -> 14 | G17: =INT(E17/F17) -> 71 | H17: =MOD(E17,F17) -> 11 | I17: =G17+IF(H17>0,1,0) -> 72 | J17: {=IF(H17>0,H17,F17)} -> 11 | K17: =E17/(I17*F17) -> 0.99702381 | L17: =G17&" × "&F17&" + "&IF(H17>0,"1 × "&H17,"0") -> 71 × 14 + 1 × 11 | M17: =MIN(E17,F17) -> 14 | N17: =IF(E17>F17,MIN(E17-F17,F17),0) -> 14 | O17: =IF(E17>2*F17,MIN(E17-2*F17,F17),0) -> 14 | P17: =IF(E17>3*F17,MIN(E17-3*F17,F17),0) -> 14 | Q17: =MAX(0,E17-4*F17) -> 949
B18: {=PO_MASTER!B33} -> 4901873568 | C18: =TEXT(PO_MASTER!L33,"000") -> 100 | D18: {=PO_MASTER!N33} -> 48 | E18: {=PO_MASTER!O33} -> 6 | F18: {=$D$5} -> 14 | G18: =INT(E18/F18) -> 0 | H18: =MOD(E18,F18) -> 6 | I18: =G18+IF(H18>0,1,0) -> 1 | J18: {=IF(H18>0,H18,F18)} -> 6 | K18: =E18/(I18*F18) -> 0.42857143 | L18: =G18&" × "&F18&" + "&IF(H18>0,"1 × "&H18,"0") -> 0 × 14 + 1 × 6 | M18: =MIN(E18,F18) -> 6 | N18: =IF(E18>F18,MIN(E18-F18,F18),0) -> 0 | O18: =IF(E18>2*F18,MIN(E18-2*F18,F18),0) -> 0 | P18: =IF(E18>3*F18,MIN(E18-3*F18,F18),0) -> 0 | Q18: =MAX(0,E18-4*F18) -> 0
B19: {=PO_MASTER!B39} -> 4901873568 | C19: =TEXT(PO_MASTER!L39,"000") -> 404 | D19: {=PO_MASTER!N39} -> 42 | E19: {=PO_MASTER!O39} -> 700 | F19: {=$D$5} -> 14 | G19: =INT(E19/F19) -> 50 | H19: =MOD(E19,F19) -> 0 | I19: =G19+IF(H19>0,1,0) -> 50 | J19: {=IF(H19>0,H19,F19)} -> 14 | K19: =E19/(I19*F19) -> 1 | L19: =G19&" × "&F19&" + "&IF(H19>0,"1 × "&H19,"0") -> 50 × 14 + 0 | M19: =MIN(E19,F19) -> 14 | N19: =IF(E19>F19,MIN(E19-F19,F19),0) -> 14 | O19: =IF(E19>2*F19,MIN(E19-2*F19,F19),0) -> 14 | P19: =IF(E19>3*F19,MIN(E19-3*F19,F19),0) -> 14 | Q19: =MAX(0,E19-4*F19) -> 644
B20: {=PO_MASTER!B43} -> 4901873568 | C20: =TEXT(PO_MASTER!L43,"000") -> 404 | D20: {=PO_MASTER!N43} -> 46 | E20: {=PO_MASTER!O43} -> 113 | F20: {=$D$5} -> 14 | G20: =INT(E20/F20) -> 8 | H20: =MOD(E20,F20) -> 1 | I20: =G20+IF(H20>0,1,0) -> 9 | J20: {=IF(H20>0,H20,F20)} -> 1 | K20: =E20/(I20*F20) -> 0.8968254 | L20: =G20&" × "&F20&" + "&IF(H20>0,"1 × "&H20,"0") -> 8 × 14 + 1 × 1 | M20: =MIN(E20,F20) -> 14 | N20: =IF(E20>F20,MIN(E20-F20,F20),0) -> 14 | O20: =IF(E20>2*F20,MIN(E20-2*F20,F20),0) -> 14 | P20: =IF(E20>3*F20,MIN(E20-3*F20,F20),0) -> 14 | Q20: =MAX(0,E20-4*F20) -> 57
B21: {=PO_MASTER!B52} -> 4901873568 | C21: =TEXT(PO_MASTER!L52,"000") -> 452 | D21: {=PO_MASTER!N52} -> 42 | E21: {=PO_MASTER!O52} -> 540 | F21: {=$D$5} -> 14 | G21: =INT(E21/F21) -> 38 | H21: =MOD(E21,F21) -> 8 | I21: =G21+IF(H21>0,1,0) -> 39 | J21: {=IF(H21>0,H21,F21)} -> 8 | K21: =E21/(I21*F21) -> 0.98901099 | L21: =G21&" × "&F21&" + "&IF(H21>0,"1 × "&H21,"0") -> 38 × 14 + 1 × 8 | M21: =MIN(E21,F21) -> 14 | N21: =IF(E21>F21,MIN(E21-F21,F21),0) -> 14 | O21: =IF(E21>2*F21,MIN(E21-2*F21,F21),0) -> 14 | P21: =IF(E21>3*F21,MIN(E21-3*F21,F21),0) -> 14 | Q21: =MAX(0,E21-4*F21) -> 484
B22: {=PO_MASTER!B57} -> 4901893255 | C22: =TEXT(PO_MASTER!L57,"000") -> 118 | D22: {=PO_MASTER!N57} -> S | E22: {=PO_MASTER!O57} -> 47 | F22: {=$D$5} -> 14 | G22: =INT(E22/F22) -> 3 | H22: =MOD(E22,F22) -> 5 | I22: =G22+IF(H22>0,1,0) -> 4 | J22: {=IF(H22>0,H22,F22)} -> 5 | K22: =E22/(I22*F22) -> 0.83928571 | L22: =G22&" × "&F22&" + "&IF(H22>0,"1 × "&H22,"0") -> 3 × 14 + 1 × 5 | M22: =MIN(E22,F22) -> 14 | N22: =IF(E22>F22,MIN(E22-F22,F22),0) -> 14 | O22: =IF(E22>2*F22,MIN(E22-2*F22,F22),0) -> 14 | P22: =IF(E22>3*F22,MIN(E22-3*F22,F22),0) -> 5 | Q22: =MAX(0,E22-4*F22) -> 0
B23: {=PO_MASTER!B59} -> 4901893255 | C23: =TEXT(PO_MASTER!L59,"000") -> 118 | D23: {=PO_MASTER!N59} -> L | E23: {=PO_MASTER!O59} -> 164 | F23: {=$D$5} -> 14 | G23: =INT(E23/F23) -> 11 | H23: =MOD(E23,F23) -> 10 | I23: =G23+IF(H23>0,1,0) -> 12 | J23: {=IF(H23>0,H23,F23)} -> 10 | K23: =E23/(I23*F23) -> 0.97619048 | L23: =G23&" × "&F23&" + "&IF(H23>0,"1 × "&H23,"0") -> 11 × 14 + 1 × 10 | M23: =MIN(E23,F23) -> 14 | N23: =IF(E23>F23,MIN(E23-F23,F23),0) -> 14 | O23: =IF(E23>2*F23,MIN(E23-2*F23,F23),0) -> 14 | P23: =IF(E23>3*F23,MIN(E23-3*F23,F23),0) -> 14 | Q23: =MAX(0,E23-4*F23) -> 108
B24: {=PO_MASTER!B65} -> 4901893255 | C24: =TEXT(PO_MASTER!L65,"000") -> 404 | D24: {=PO_MASTER!N65} -> L | E24: {=PO_MASTER!O65} -> 73 | F24: {=$D$5} -> 14 | G24: =INT(E24/F24) -> 5 | H24: =MOD(E24,F24) -> 3 | I24: =G24+IF(H24>0,1,0) -> 6 | J24: {=IF(H24>0,H24,F24)} -> 3 | K24: =E24/(I24*F24) -> 0.86904762 | L24: =G24&" × "&F24&" + "&IF(H24>0,"1 × "&H24,"0") -> 5 × 14 + 1 × 3 | M24: =MIN(E24,F24) -> 14 | N24: =IF(E24>F24,MIN(E24-F24,F24),0) -> 14 | O24: =IF(E24>2*F24,MIN(E24-2*F24,F24),0) -> 14 | P24: =IF(E24>3*F24,MIN(E24-3*F24,F24),0) -> 14 | Q24: =MAX(0,E24-4*F24) -> 17
B25: {=PO_MASTER!B68} -> 4901893255 | C25: =TEXT(PO_MASTER!L68,"000") -> 404 | D25: {=PO_MASTER!N68} -> XXXL | E25: {=PO_MASTER!O68} -> 4 | F25: {=$D$5} -> 14 | G25: =INT(E25/F25) -> 0 | H25: =MOD(E25,F25) -> 4 | I25: =G25+IF(H25>0,1,0) -> 1 | J25: {=IF(H25>0,H25,F25)} -> 4 | K25: =E25/(I25*F25) -> 0.28571429 | L25: =G25&" × "&F25&" + "&IF(H25>0,"1 × "&H25,"0") -> 0 × 14 + 1 × 4 | M25: =MIN(E25,F25) -> 4 | N25: =IF(E25>F25,MIN(E25-F25,F25),0) -> 0 | O25: =IF(E25>2*F25,MIN(E25-2*F25,F25),0) -> 0 | P25: =IF(E25>3*F25,MIN(E25-3*F25,F25),0) -> 0 | Q25: =MAX(0,E25-4*F25) -> 0
B26: {=PO_MASTER!B71} -> 4901893255 | C26: =TEXT(PO_MASTER!L71,"000") -> 923 | D26: {=PO_MASTER!N71} -> L | E26: {=PO_MASTER!O71} -> 508 | F26: {=$D$5} -> 14 | G26: =INT(E26/F26) -> 36 | H26: =MOD(E26,F26) -> 4 | I26: =G26+IF(H26>0,1,0) -> 37 | J26: {=IF(H26>0,H26,F26)} -> 4 | K26: =E26/(I26*F26) -> 0.98069498 | L26: =G26&" × "&F26&" + "&IF(H26>0,"1 × "&H26,"0") -> 36 × 14 + 1 × 4 | M26: =MIN(E26,F26) -> 14 | N26: =IF(E26>F26,MIN(E26-F26,F26),0) -> 14 | O26: =IF(E26>2*F26,MIN(E26-2*F26,F26),0) -> 14 | P26: =IF(E26>3*F26,MIN(E26-3*F26,F26),0) -> 14 | Q26: =MAX(0,E26-4*F26) -> 452
B27: {=PO_MASTER!B74} -> 4901893255 | C27: =TEXT(PO_MASTER!L74,"000") -> 923 | D27: {=PO_MASTER!N74} -> XXXL | E27: {=PO_MASTER!O74} -> 33 | F27: {=$D$5} -> 14 | G27: =INT(E27/F27) -> 2 | H27: =MOD(E27,F27) -> 5 | I27: =G27+IF(H27>0,1,0) -> 3 | J27: {=IF(H27>0,H27,F27)} -> 5 | K27: =E27/(I27*F27) -> 0.78571429 | L27: =G27&" × "&F27&" + "&IF(H27>0,"1 × "&H27,"0") -> 2 × 14 + 1 × 5 | M27: =MIN(E27,F27) -> 14 | N27: =IF(E27>F27,MIN(E27-F27,F27),0) -> 14 | O27: =IF(E27>2*F27,MIN(E27-2*F27,F27),0) -> 5 | P27: =IF(E27>3*F27,MIN(E27-3*F27,F27),0) -> 0 | Q27: =MAX(0,E27-4*F27) -> 0
B28: TOTALS | E28: =SUM(E12:E27) -> 4663 | G28: =SUM(G12:G27) -> 328 | H28: =SUM(H12:H27) -> 71 | I28: =SUM(I12:I27) -> 342 | K28: =AVERAGE(K12:K27) -> 0.80028636 | M28: =SUM(M12:M27) -> 193 | N28: =SUM(N12:N27) -> 182 | O28: =SUM(O12:O27) -> 161 | P28: =SUM(P12:P27) -> 145 | Q28: =SUM(Q12:Q27) -> 3982
B30: CLASSIC EXAMPLE • 113 pcs ÷ 14 pcs/carton
B31: Input Qty | C31: Capacity | D31: Formula: INT(113/14) | E31: Full Cartons | F31: Formula: MOD(113,14) | G31: Remainder | H31: Total Cartons
B32: 113 | C32: 14 | D32: INT(113/14) | E32: =INT(B32/C32) -> 8 | F32: MOD(113,14) | G32: =MOD(B32,C32) -> 1 | H32: =E32+IF(G32>0,1,0) -> 9
B34: OUTPUT DISTRIBUTION:
B35: 14 | 14 | 14 | 14 | 14 | 14 | 14 | 14 | 1 | J35: 8 full cartons of 14 pcs + 1 partial carton of 1 pc = 9 total cartons
B37: Ctn 1 | C37: Ctn 2 | D37: Ctn 3 | E37: Ctn 4 | F37: Ctn 5 | G37: Ctn 6 | H37: Ctn 7 | I37: Ctn 8 | J37: Ctn 9
B38: 14 | C38: 14 | D38: 14 | E38: 14 | F38: 14 | G38: 14 | H38: 14 | I38: 14 | J38: 1
B40: CAPACITY COMPARISON — Effect on Total Cartons
B41: Sample Qty | C41: Cap=10 | D41: Cap=12 | E41: Cap=14 | F41: Cap=15 | G41: Cap=18 | H41: Cap=20 | I41: Best Cap | J41: Best Total | K41: Notes
B42: 113 | C42: =ROUNDUP(B42/10,0) -> 12 | D42: =ROUNDUP(B42/12,0) -> 10 | E42: =ROUNDUP(B42/14,0) -> 9 | F42: =ROUNDUP(B42/15,0) -> 8 | G42: =ROUNDUP(B42/18,0) -> 7 | H42: =ROUNDUP(B42/20,0) -> 6 | I42: =INDEX({10,12,14,15,18,20},MATCH(MIN(C42:H42),C42:H42,0)) -> 20 | J42: =MIN(C42:H42) -> 6 | K42: Classic 113 example
B43: 597 | C43: =ROUNDUP(B43/10,0) -> 60 | D43: =ROUNDUP(B43/12,0) -> 50 | E43: =ROUNDUP(B43/14,0) -> 43 | F43: =ROUNDUP(B43/15,0) -> 40 | G43: =ROUNDUP(B43/18,0) -> 34 | H43: =ROUNDUP(B43/20,0) -> 30 | I43: =INDEX({10,12,14,15,18,20},MATCH(MIN(C43:H43),C43:H43,0)) -> 20 | J43: =MIN(C43:H43) -> 30 | K43: Style 001 Sz40
B44: 280 | C44: =ROUNDUP(B44/10,0) -> 28 | D44: =ROUNDUP(B44/12,0) -> 24 | E44: =ROUNDUP(B44/14,0) -> 20 | F44: =ROUNDUP(B44/15,0) -> 19 | G44: =ROUNDUP(B44/18,0) -> 16 | H44: =ROUNDUP(B44/20,0) -> 14 | I44: =INDEX({10,12,14,15,18,20},MATCH(MIN(C44:H44),C44:H44,0)) -> 20 | J44: =MIN(C44:H44) -> 14 | K44: Style 001 Sz46
B45: 47 | C45: =ROUNDUP(B45/10,0) -> 5 | D45: =ROUNDUP(B45/12,0) -> 4 | E45: =ROUNDUP(B45/14,0) -> 4 | F45: =ROUNDUP(B45/15,0) -> 4 | G45: =ROUNDUP(B45/18,0) -> 3 | H45: =ROUNDUP(B45/20,0) -> 3 | I45: =INDEX({10,12,14,15,18,20},MATCH(MIN(C45:H45),C45:H45,0)) -> 18 | J45: =MIN(C45:H45) -> 3 | K45: Style 118 Sz S
B46: 1005 | C46: =ROUNDUP(B46/10,0) -> 101 | D46: =ROUNDUP(B46/12,0) -> 84 | E46: =ROUNDUP(B46/14,0) -> 72 | F46: =ROUNDUP(B46/15,0) -> 67 | G46: =ROUNDUP(B46/18,0) -> 56 | H46: =ROUNDUP(B46/20,0) -> 51 | I46: =INDEX({10,12,14,15,18,20},MATCH(MIN(C46:H46),C46:H46,0)) -> 20 | J46: =MIN(C46:H46) -> 51 | K46: Style 100 Sz40 max
B47: 508 | C47: =ROUNDUP(B47/10,0) -> 51 | D47: =ROUNDUP(B47/12,0) -> 43 | E47: =ROUNDUP(B47/14,0) -> 37 | F47: =ROUNDUP(B47/15,0) -> 34 | G47: =ROUNDUP(B47/18,0) -> 29 | H47: =ROUNDUP(B47/20,0) -> 26 | I47: =INDEX({10,12,14,15,18,20},MATCH(MIN(C47:H47),C47:H47,0)) -> 20 | J47: =MIN(C47:H47) -> 26 | K47: Style 923 Sz L
...

Sheet CUT_SHEET
A1: CUT SHEET — Production vs Packing Comparison
A2: Track cutting, packing, and balance for each PO Color+Size line
B4: Total Ordered | D4: Total Cut | F4: Total Packed | H4: Balance | J4: Overall % | L4: Lines Complete
B5: =SUM(F8:F77) -> 19450 | D5: =SUM(G8:G77) -> 19533 | F5: =SUM(H8:H77) -> 19406 | H5: =B5-F5 -> 44 | J5: =IFERROR(F5/B5,0) -> 0.99773779 | L5: =COUNTIF(L8:L77,"Complete")&" / "&COUNTA(L8:L77) -> 31 / 70
B7: PO Number | C7: Style | D7: Color | E7: Size | F7: Order Qty | G7: Cut Qty | H7: Packed Qty | I7: Balance | J7: Difference | K7: % | L7: Status | M7: Notes
B8: {=PO_MASTER!B5} -> 4901873568 | C8: {=PO_MASTER!H5} -> 50473265 | D8: =TEXT(PO_MASTER!L5,"000") -> 001 | E8: {=PO_MASTER!N5} -> 37 | F8: {=PO_MASTER!O5} -> 50 | G8: =MAX(0,F8+IF(MOD(ROW(),7)=0,-3,IF(MOD(ROW(),5)=0,5,IF(MOD(ROW(),3)=0,-1,2)))) -> 52 | H8: =MAX(0,MIN(G8,F8+IF(MOD(ROW(),11)=0,3,IF(MOD(ROW(),4)=0,-1,0)))) -> 49 | I8: =F8-H8 -> 1 | J8: =H8-F8 -> -1 | K8: =IFERROR(H8/F8,0) -> 0.98 | L8: =IF(H8>F8,"Over Packed",IF(H8=F8,"Complete",IF(H8>=F8*0.98,"Near Complete","Under Packed"))) -> Near Complete | M8: =IF(H8>F8,"Excess: "&(H8-F8)&" pcs",IF(H8=F8,"On target",IF(I8>0,"Short: "&I8&" pcs",""))) -> Short: 1 pcs
B9: {=PO_MASTER!B6} -> 4901873568 | C9: {=PO_MASTER!H6} -> 50473265 | D9: =TEXT(PO_MASTER!L6,"000") -> 001 | E9: {=PO_MASTER!N6} -> 38 | F9: {=PO_MASTER!O6} -> 210 | G9: =MAX(0,F9+IF(MOD(ROW(),7)=0,-3,IF(MOD(ROW(),5)=0,5,IF(MOD(ROW(),3)=0,-1,2)))) -> 209 | H9: =MAX(0,MIN(G9,F9+IF(MOD(ROW(),11)=0,3,IF(MOD(ROW(),4)=0,-1,0)))) -> 209 | I9: =F9-H9 -> 1 | J9: =H9-F9 -> -1 | K9: =IFERROR(H9/F9,0) -> 0.9952381 | L9: =IF(H9>F9,"Over Packed",IF(H9=F9,"Complete",IF(H9>=F9*0.98,"Near Complete","Under Packed"))) -> Near Complete | M9: =IF(H9>F9,"Excess: "&(H9-F9)&" pcs",IF(H9=F9,"On target",IF(I9>0,"Short: "&I9&" pcs",""))) -> Short: 1 pcs
B10: {=PO_MASTER!B7} -> 4901873568 | C10: {=PO_MASTER!H7} -> 50473265 | D10: =TEXT(PO_MASTER!L7,"000") -> 001 | E10: {=PO_MASTER!N7} -> 39 | F10: {=PO_MASTER!O7} -> 524 | G10: =MAX(0,F10+IF(MOD(ROW(),7)=0,-3,IF(MOD(ROW(),5)=0,5,IF(MOD(ROW(),3)=0,-1,2)))) -> 529 | H10: =MAX(0,MIN(G10,F10+IF(MOD(ROW(),11)=0,3,IF(MOD(ROW(),4)=0,-1,0)))) -> 524 | I10: =F10-H10 -> 0 | J10: =H10-F10 -> 0 | K10: =IFERROR(H10/F10,0) -> 1 | L10: =IF(H10>F10,"Over Packed",IF(H10=F10,"Complete",IF(H10>=F10*0.98,"Near Complete","Under Packed"))) -> Complete | M10: =IF(H10>F10,"Excess: "&(H10-F10)&" pcs",IF(H10=F10,"On target",IF(I10>0,"Short: "&I10&" pcs",""))) -> On target
B11: {=PO_MASTER!B8} -> 4901873568 | C11: {=PO_MASTER!H8} -> 50473265 | D11: =TEXT(PO_MASTER!L8,"000") -> 001 | E11: {=PO_MASTER!N8} -> 40 | F11: {=PO_MASTER!O8} -> 597 | G11: =MAX(0,F11+IF(MOD(ROW(),7)=0,-3,IF(MOD(ROW(),5)=0,5,IF(MOD(ROW(),3)=0,-1,2)))) -> 599 | H11: =MAX(0,MIN(G11,F11+IF(MOD(ROW(),11)=0,3,IF(MOD(ROW(),4)=0,-1,0)))) -> 599 | I11: =F11-H11 -> -2 | J11: =H11-F11 -> 2 | K11: =IFERROR(H11/F11,0) -> 1.0033501 | L11: =IF(H11>F11,"Over Packed",IF(H11=F11,"Complete",IF(H11>=F11*0.98,"Near Complete","Under Packed"))) -> Over Packed | M11: =IF(H11>F11,"Excess: "&(H11-F11)&" pcs",IF(H11=F11,"On target",IF(I11>0,"Short: "&I11&" pcs",""))) -> Excess: 2 pcs
B12: {=PO_MASTER!B9} -> 4901873568 | C12: {=PO_MASTER!H9} -> 50473265 | D12: =TEXT(PO_MASTER!L9,"000") -> 001 | E12: {=PO_MASTER!N9} -> 41 | F12: {=PO_MASTER!O9} -> 443 | G12: =MAX(0,F12+IF(MOD(ROW(),7)=0,-3,IF(MOD(ROW(),5)=0,5,IF(MOD(ROW(),3)=0,-1,2)))) -> 442 | H12: =MAX(0,MIN(G12,F12+IF(MOD(ROW(),11)=0,3,IF(MOD(ROW(),4)=0,-1,0)))) -> 442 | I12: =F12-H12 -> 1 | J12: =H12-F12 -> -1 | K12: =IFERROR(H12/F12,0) -> 0.99774266 | L12: =IF(H12>F12,"Over Packed",IF(H12=F12,"Complete",IF(H12>=F12*0.98,"Near Complete","Under Packed"))) -> Near Complete | M12: =IF(H12>F12,"Excess: "&(H12-F12)&" pcs",IF(H12=F12,"On target",IF(I12>0,"Short: "&I12&" pcs",""))) -> Short: 1 pcs
B13: {=PO_MASTER!B10} -> 4901873568 | C13: {=PO_MASTER!H10} -> 50473265 | D13: =TEXT(PO_MASTER!L10,"000") -> 001 | E13: {=PO_MASTER!N10} -> 42 | F13: {=PO_MASTER!O10} -> 608 | G13: =MAX(0,F13+IF(MOD(ROW(),7)=0,-3,IF(MOD(ROW(),5)=0,5,IF(MOD(ROW(),3)=0,-1,2)))) -> 610 | H13: =MAX(0,MIN(G13,F13+IF(MOD(ROW(),11)=0,3,IF(MOD(ROW(),4)=0,-1,0)))) -> 608 | I13: =F13-H13 -> 0 | J13: =H13-F13 -> 0 | K13: =IFERROR(H13/F13,0) -> 1 | L13: =IF(H13>F13,"Over Packed",IF(H13=F13,"Complete",IF(H13>=F13*0.98,"Near Complete","Under Packed"))) -> Complete | M13: =IF(H13>F13,"Excess: "&(H13-F13)&" pcs",IF(H13=F13,"On target",IF(I13>0,"Short: "&I13&" pcs",""))) -> On target
B14: {=PO_MASTER!B11} -> 4901873568 | C14: {=PO_MASTER!H11} -> 50473265 | D14: =TEXT(PO_MASTER!L11,"000") -> 001 | E14: {=PO_MASTER!N11} -> 43 | F14: {=PO_MASTER!O11} -> 562 | G14: =MAX(0,F14+IF(MOD(ROW(),7)=0,-3,IF(MOD(ROW(),5)=0,5,IF(MOD(ROW(),3)=0,-1,2)))) -> 559 | H14: =MAX(0,MIN(G14,F14+IF(MOD(ROW(),11)=0,3,IF(MOD(ROW(),4)=0,-1,0)))) -> 559 | I14: =F14-H14 -> 3 | J14: =H14-F14 -> -3 | K14: =IFERROR(H14/F14,0) -> 0.99466192 | L14: =IF(H14>F14,"Over Packed",IF(H14=F14,"Complete",IF(H14>=F14*0.98,"Near Complete","Under Packed"))) -> Near Complete | M14: =IF(H14>F14,"Excess: "&(H14-F14)&" pcs",IF(H14=F14,"On target",IF(I14>0,"Short: "&I14&" pcs",""))) -> Short: 3 pcs
B15: {=PO_MASTER!B12} -> 4901873568 | C15: {=PO_MASTER!H12} -> 50473265 | D15: =TEXT(PO_MASTER!L12,"000") -> 001 | E15: {=PO_MASTER!N12} -> 44 | F15: {=PO_MASTER!O12} -> 482 | G15: =MAX(0,F15+IF(MOD(ROW(),7)=0,-3,IF(MOD(ROW(),5)=0,5,IF(MOD(ROW(),3)=0,-1,2)))) -> 487 | H15: =MAX(0,MIN(G15,F15+IF(MOD(ROW(),11)=0,3,IF(MOD(ROW(),4)=0,-1,0)))) -> 482 | I15: =F15-H15 -> 0 | J15: =H15-F15 -> 0 | K15: =IFERROR(H15/F15,0) -> 1 | L15: =IF(H15>F15,"Over Packed",IF(H15=F15,"Complete",IF(H15>=F15*0.98,"Near Complete","Under Packed"))) -> Complete | M15: =IF(H15>F15,"Excess: "&(H15-F15)&" pcs",IF(H15=F15,"On target",IF(I15>0,"Short: "&I15&" pcs",""))) -> On target
B16: {=PO_MASTER!B13} -> 4901873568 | C16: {=PO_MASTER!H13} -> 50473265 | D16: =TEXT(PO_MASTER!L13,"000") -> 001 | E16: {=PO_MASTER!N13} -> 45 | F16: {=PO_MASTER!O13} -> 303 | G16: =MAX(0,F16+IF(MOD(ROW(),7)=0,-3,IF(MOD(ROW(),5)=0,5,IF(MOD(ROW(),3)=0,-1,2)))) -> 305 | H16: =MAX(0,MIN(G16,F16+IF(MOD(ROW(),11)=0,3,IF(MOD(ROW(),4)=0,-1,0)))) -> 302 | I16: =F16-H16 -> 1 | J16: =H16-F16 -> -1 | K16: =IFERROR(H16/F16,0) -> 0.99669967 | L16: =IF(H16>F16,"Over Packed",IF(H16=F16,"Complete",IF(H16>=F16*0.98,"Near Complete","Under Packed"))) -> Near Complete | M16: =IF(H16>F16,"Excess: "&(H16-F16)&" pcs",IF(H16=F16,"On target",IF(I16>0,"Short: "&I16&" pcs",""))) -> Short: 1 pcs
B17: {=PO_MASTER!B14} -> 4901873568 | C17: {=PO_MASTER!H14} -> 50473265 | D17: =TEXT(PO_MASTER!L14,"000") -> 001 | E17: {=PO_MASTER!N14} -> 46 | F17: {=PO_MASTER!O14} -> 280 | G17: =MAX(0,F17+IF(MOD(ROW(),7)=0,-3,IF(MOD(ROW(),5)=0,5,IF(MOD(ROW(),3)=0,-1,2)))) -> 282 | H17: =MAX(0,MIN(G17,F17+IF(MOD(ROW(),11)=0,3,IF(MOD(ROW(),4)=0,-1,0)))) -> 280 | I17: =F17-H17 -> 0 | J17: =H17-F17 -> 0 | K17: =IFERROR(H17/F17,0) -> 1 | L17: =IF(H17>F17,"Over Packed",IF(H17=F17,"Complete",IF(H17>=F17*0.98,"Near Complete","Under Packed"))) -> Complete | M17: =IF(H17>F17,"Excess: "&(H17-F17)&" pcs",IF(H17=F17,"On target",IF(I17>0,"Short: "&I17&" pcs",""))) -> On target
B18: {=PO_MASTER!B15} -> 4901873568 | C18: {=PO_MASTER!H15} -> 50473265 | D18: =TEXT(PO_MASTER!L15,"000") -> 001 | E18: {=PO_MASTER!N15} -> 47 | F18: {=PO_MASTER!O15} -> 1 | G18: =MAX(0,F18+IF(MOD(ROW(),7)=0,-3,IF(MOD(ROW(),5)=0,5,IF(MOD(ROW(),3)=0,-1,2)))) -> 0 | H18: =MAX(0,MIN(G18,F18+IF(MOD(ROW(),11)=0,3,IF(MOD(ROW(),4)=0,-1,0)))) -> 0 | I18: =F18-H18 -> 1 | J18: =H18-F18 -> -1 | K18: =IFERROR(H18/F18,0) -> 0 | L18: =IF(H18>F18,"Over Packed",IF(H18=F18,"Complete",IF(H18>=F18*0.98,"Near Complete","Under Packed"))) -> Under Packed | M18: =IF(H18>F18,"Excess: "&(H18-F18)&" pcs",IF(H18=F18,"On target",IF(I18>0,"Short: "&I18&" pcs",""))) -> Short: 1 pcs
B19: {=PO_MASTER!B16} -> 4901873568 | C19: {=PO_MASTER!H16} -> 50473265 | D19: =TEXT(PO_MASTER!L16,"000") -> 001 | E19: {=PO_MASTER!N16} -> 48 | F19: {=PO_MASTER!O16} -> 12 | G19: =MAX(0,F19+IF(MOD(ROW(),7)=0,-3,IF(MOD(ROW(),5)=0,5,IF(MOD(ROW(),3)=0,-1,2)))) -> 14 | H19: =MAX(0,MIN(G19,F19+IF(MOD(ROW(),11)=0,3,IF(MOD(ROW(),4)=0,-1,0)))) -> 12 | I19: =F19-H19 -> 0 | J19: =H19-F19 -> 0 | K19: =IFERROR(H19/F19,0) -> 1 | L19: =IF(H19>F19,"Over Packed",IF(H19=F19,"Complete",IF(H19>=F19*0.98,"Near Complete","Under Packed"))) -> Complete | M19: =IF(H19>F19,"Excess: "&(H19-F19)&" pcs",IF(H19=F19,"On target",IF(I19>0,"Short: "&I19&" pcs",""))) -> On target
... B77: {=PO_MASTER!B74} -> 4901893255 | C77: {=PO_MASTER!H74} -> 50576239 | D77: =TEXT(PO_MASTER!L74,"000") -> 923 | E77: {=PO_MASTER!N74} -> XXXL | F77: {=PO_MASTER!O74} -> 33 | G77: =MAX(0,F77+IF(MOD(ROW(),7)=0,-3,IF(MOD(ROW(),5)=0,5,IF(MOD(ROW(),3)=0,-1,2)))) -> 30 | H77: =MAX(0,MIN(G77,F77+IF(MOD(ROW(),11)=0,3,IF(MOD(ROW(),4)=0,-1,0)))) -> 30 | I77: =F77-H77 -> 3 | J77: =H77-F77 -> -3 | K77: =IFERROR(H77/F77,0) -> 0.90909091 | L77: =IF(H77>F77,"Over Packed",IF(H77=F77,"Complete",IF(H77>=F77*0.98,"Near Complete","Under Packed"))) -> Under Packed | M77: =IF(H77>F77,"Excess: "&(H77-F77)&" pcs",IF(H77=F77,"On target",IF(I77>0,"Short: "&I77&" pcs",""))) -> Short: 3 pcs
B78: TOTALS | F78: =SUM(F8:F77) -> 19450 | G78: =SUM(G8:G77) -> 19533 | H78: =SUM(H8:H77) -> 19406 | I78: =SUM(I8:I77) -> 44 | J78: =SUM(J8:J77) -> -44 | K78: =IFERROR(H78/F78,0) -> 0.99773779 | L78: =COUNTIF(L8:L77,"Complete")&" of "&COUNTA(L8:L77)&" complete" -> 31 of 70 complete
B80: STATUS LEGEND
B81: Over Packed | D81: Complete | F81: Near Complete (>98%) | H81: Under Packed | J81: Highlights help identify production gaps at a glance

Sheet MASTER_DATA
A1: MASTER DATA — Lookup Tables & Reference Lists
A2: All lookups used by PO Master, Packing List, Carton Allocation. Editable by user.
B4: COLORS
B5: Code | C5: Description | D5: Family
B6: 1 | C6: Black | D6: Dark
B7: 100 | C7: White | D7: Light
B8: 118 | C8: Open White | D8: Light
B9: 404 | C9: Dark Blue | D9: Dark
B10: 452 | C10: Light Blue | D10: Light
B11: 923 | C11: Beige Overflow | D11: Neutral
B12: 200 | C12: Grey Melange | D12: Neutral
B13: 610 | C13: Navy | D13: Dark
B15: SIZES
B16: Size | C16: Type | D16: Sort Order
B17: 37 | C17: Numeric | D17: 1
B18: 38 | C18: Numeric | D18: 2
B19: 39 | C19: Numeric | D19: 3
B20: 40 | C20: Numeric | D20: 4
B21: 41 | C21: Numeric | D21: 5
B22: 42 | C22: Numeric | D22: 6
B23: 43 | C23: Numeric | D23: 7
B24: 44 | C24: Numeric | D24: 8
B25: 45 | C25: Numeric | D25: 9
B26: 46 | C26: Numeric | D26: 10
B27: 47 | C27: Numeric | D27: 11
B28: 48 | C28: Numeric | D28: 12
... B30: 50 | C30: Numeric | D30: 14
B31: 42L | C31: Numeric-Long | D31: 15
B32: 43L | C32: Numeric-Long | D32: 16
B33: 44L | C33: Numeric-Long | D33: 17
B34: 45L | C34: Numeric-Long | D34: 18
B35: XS | C35: Alpha | D35: 1
B36: S | C36: Alpha | D36: 2
B37: M | C37: Alpha | D37: 3
B38: L | C38: Alpha | D38: 4
B39: XL | C39: Alpha | D39: 5
B40: XXL | C40: Alpha | D40: 6
B41: XXXL | C41: Alpha | D41: 7
B42: 4XL | C42: Alpha | D42: 8
B43: 5XL | C43: Alpha | D43: 9
...

Sheet SETTINGS
A1: SETTINGS — Workbook Configuration
A2: User configurable parameters. Yellow cells are editable input fields.
B4: GENERAL SETTINGS
B5: Setting | C5: Value | D5: Description
B6: Carton Capacity (pcs) | C6: 14 | D6: Default pieces per carton (options: 10,12,14,15,18,20)
B7: Default Net Weight (g/pc) | C7: 300 | D7: Applied when style not in Weight Master
B8: Default Carton Weight (g) | C8: 1200 | D8: Empty carton tare weight
B9: Tolerance (%) | C9: 2 | D9: Acceptable variance packed vs ordered
B10: Print Area | C10: A1:AZ100 | D10: Range printed by Export PDF
B11: Export Folder | C11: C:\HugoBoss\Exports | D11: Save location for exports
B12: Auto Save (min) | C12: 10 | D12: Auto-save interval
B13: Sheet Protection Pwd | C13: hb2026 | D13: Password locks Master/Settings/Dashboard
B14: Company Logo | C14: HUGO BOSS | D14: Header logo text
B16: PACKING LIST DEFAULTS
B17: Field | C17: Value | D17: Notes
B18: Default Shipment | C18: SCC Sea freight | D18: Applied on new packing list
B19: Default Terms of Delivery | C19: FOB IN_MAA | D19: Standard delivery terms
B20: Default Payment | C20: 100 days due net | D20: Standard payment terms
B21: Default Currency | C21: USD | D21: Standard currency
B22: PL Prefix | C22: PL- | D22: Auto-generated packing list number prefix
B23: Invoice Prefix | C23: INV- | D23: Auto-generated invoice number prefix
B25: SYSTEM INFO
B26: Property | C26: Value | D26: Note
B27: Workbook Version | C27: 1.0.0 | D27: Current version
B28: Build Date | C28: 02.07.2026 | D28: Release build date
B29: Author | C29: Hugo Boss Packing Team | D29: Owner
B30: License | C30: Internal Use Only | D30: Licence
B31: Support Email | C31: packing@hugoboss.com | D31: Contact
B32: Last Backup | C32: 02.07.2026 | D32: Latest backup date

Sheet DASHBOARD
B1: HUGO BOSS — EXECUTIVE DASHBOARD
B2: Packing Progress · KPI Overview · Analytical Charts | Data refreshed 02.07.2026
B4: TOTAL POs | D4: TOTAL ORDERED (pcs) | F4: PACKED (pcs) | H4: REMAINING (pcs) | J4: TOTAL CARTONS | L4: COMPLETION %
B5: {=SUMPRODUCT(1/COUNTIF(PO_MASTER!B5:B74,PO_MASTER!B5:B74))} -> 2 | D5: =SUM(PO_MASTER!O5:O74) -> 19450 | F5: =SUM(CUT_SHEET!H8:H77) -> 19406 | H5: =D5-F5 -> 44 | J5: {=SUMPRODUCT(CEILING(PO_MASTER!O5:O74,SETTINGS!C6)/SETTINGS!C6)} -> 1425 | L5: =F5/D5 -> 0.99773779
B7: TOTAL NET WEIGHT (kg) | E7: TOTAL GROSS WEIGHT (kg) | H7: TOTAL CBM (m³) | K7: AVG COMPLETION / LINE
B8: =F5*0.3 -> 5821.8 | E8: =B8+J5*1.2 -> 7531.8 | H8: =J5*0.06 -> 85.5 | K8: =AVERAGE(CUT_SHEET!K8:K77) -> 0.95382796
B10: AGGREGATION TABLES (Chart Source Data)
B11: Packed by Color | D11: Packed by Style | F11: Packed by Size | H11: Packed by PO | J11: Ordered vs Remaining
B12: Color | C12: Packed Qty | D12: Style | E12: Packed Qty | F12: Size | G12: Packed Qty | H12: PO Number | I12: Packed Qty | J12: PO | K12: Packed | L12: Remaining
B13: 001 Black | C13: =SUMIFS(CUT_SHEET!H8:H77,CUT_SHEET!D8:D77,"001") -> 4186 | D13: 50473265 | E13: =SUMIFS(CUT_SHEET!H8:H77,CUT_SHEET!C8:C77,50473265) -> 16917 | F13: 37 | G13: =SUMIFS(CUT_SHEET!H8:H77,CUT_SHEET!E8:E77,37) -> 138 | H13: 4901873568 | I13: =SUMIFS(CUT_SHEET!H8:H77,CUT_SHEET!B8:B77,4901873568) -> 16917 | J13: 4901873568 | K13: {=I13} -> 16917 | L13: =16945-K13 -> 28
B14: 100 White | C14: =SUMIFS(CUT_SHEET!H8:H77,CUT_SHEET!D8:D77,"100") -> 6074 | D14: 50576239 | E14: =SUMIFS(CUT_SHEET!H8:H77,CUT_SHEET!C8:C77,50576239) -> 2489 | F14: 38 | G14: =SUMIFS(CUT_SHEET!H8:H77,CUT_SHEET!E8:E77,38) -> 950 | H14: 4901893255 | I14: =SUMIFS(CUT_SHEET!H8:H77,CUT_SHEET!B8:B77,4901893255) -> 2489 | J14: 4901893255 | K14: {=I14} -> 2489 | L14: =2505-K14 -> 16
B15: 118 Open White | C15: =SUMIFS(CUT_SHEET!H8:H77,CUT_SHEET!D8:D77,"118") -> 579 | F15: 39 | G15: =SUMIFS(CUT_SHEET!H8:H77,CUT_SHEET!E8:E77,39) -> 1761
B16: 404 Dark Blue | C16: =SUMIFS(CUT_SHEET!H8:H77,CUT_SHEET!D8:D77,"404") -> 4011 | F16: 40 | G16: =SUMIFS(CUT_SHEET!H8:H77,CUT_SHEET!E8:E77,40) -> 2559
B17: 452 Light Blue | C17: =SUMIFS(CUT_SHEET!H8:H77,CUT_SHEET!D8:D77,"452") -> 2832 | F17: 41 | G17: =SUMIFS(CUT_SHEET!H8:H77,CUT_SHEET!E8:E77,41) -> 2328
B18: 923 Beige | C18: =SUMIFS(CUT_SHEET!H8:H77,CUT_SHEET!D8:D77,"923") -> 1724 | F18: 42 | G18: =SUMIFS(CUT_SHEET!H8:H77,CUT_SHEET!E8:E77,42) -> 2842
F19: 43 | G19: =SUMIFS(CUT_SHEET!H8:H77,CUT_SHEET!E8:E77,43) -> 2457
F20: 44 | G20: =SUMIFS(CUT_SHEET!H8:H77,CUT_SHEET!E8:E77,44) -> 1783 | H20: Daily Progress (Simulated)
F21: 45 | G21: =SUMIFS(CUT_SHEET!H8:H77,CUT_SHEET!E8:E77,45) -> 1041 | H21: Date | I21: Cumulative Packed | J21: Daily Delta
F22: 46 | G22: =SUMIFS(CUT_SHEET!H8:H77,CUT_SHEET!E8:E77,46) -> 845 | H22: 25.06.2026 | I22: 1000 | J22: 1000
F23: 47 | G23: =SUMIFS(CUT_SHEET!H8:H77,CUT_SHEET!E8:E77,47) -> 0 | H23: 26.06.2026 | I23: 3200 | J23: 2200
F24: 48 | G24: =SUMIFS(CUT_SHEET!H8:H77,CUT_SHEET!E8:E77,48) -> 17 | H24: 27.06.2026 | I24: 6100 | J24: 2900
F25: 49 | G25: =SUMIFS(CUT_SHEET!H8:H77,CUT_SHEET!E8:E77,49) -> 1 | H25: 28.06.2026 | I25: 9400 | J25: 3300
F26: 50 | G26: =SUMIFS(CUT_SHEET!H8:H77,CUT_SHEET!E8:E77,50) -> 0 | H26: 29.06.2026 | I26: 12200 | J26: 2800
F27: 42L | G27: =SUMIFS(CUT_SHEET!H8:H77,CUT_SHEET!E8:E77,"42L") -> 12 | H27: 30.06.2026 | I27: 15500 | J27: 3300
F28: 43L | G28: =SUMIFS(CUT_SHEET!H8:H77,CUT_SHEET!E8:E77,"43L") -> 70 | H28: 01.07.2026 | I28: 18000 | J28: 2500
F29: 44L | G29: =SUMIFS(CUT_SHEET!H8:H77,CUT_SHEET!E8:E77,"44L") -> 71 | H29: 02.07.2026 | I29: 19406 | J29: 1406
F30: 45L | G30: =SUMIFS(CUT_SHEET!H8:H77,CUT_SHEET!E8:E77,"45L") -> 42
B32: ANALYTICAL CHARTS
B65: © 2026 Hugo Boss Packing List System • Data sources: PO_MASTER, CUT_SHEET, CARTON_ALLOCATION

Sheet EXPORT
B1: EXPORT CENTER — Deliverables Staging
B2: Generate print-ready, PDF, macro-free XLSX, or email packages from the current packing list
B4: CURRENT JOB
B5: Job Name: | D5: HugoBoss_PO_4901873568_PackingList | G5: ="Created: "&TEXT(TODAY(),"DD.MM.YYYY") -> Created: 03.07.2026
B6: PO Number: | D6: 4901873568 | E6: Style: | F6: 50473265 | G6: Cartons: | H6: {=DASHBOARD!J5} -> 1425
B7: Total Qty: | D7: {=DASHBOARD!D5} -> 19450 | E7: Net Weight: | F7: =DASHBOARD!B8&" kg" -> 5821.8 kg | G7: CBM: | H7: {=DASHBOARD!H8} -> 85.5
B8: Destination: | D8: DC FPG Filderstadt, Germany | G8: 22.07.2026
B10: EXPORT OPTIONS
B11: # | C11: Format | D11: Output Filename | E11: Content Included | F11: File Size (est) | G11: Status | H11: Action
B12: 1 | C12: 🖨 Print (A4 Landscape) | D12: PackingList_PO4901873568_Print.pdf | E12: Packing List + Summary | F12: ~180 KB | G12: Ready | H12: Generate
B13: 2 | C13: 📄 PDF (Multi-page) | D13: PackingList_PO4901873568.pdf | E13: All Sheets + Charts | F13: ~1.2 MB | G13: Ready | H13: Generate
B14: 3 | C14: 💾 Macro-free XLSX | D14: PackingList_PO4901873568.xlsx | E14: Packing/Summary/Dashboard (values only) | F14: ~380 KB | G14: Ready | H14: Generate
B15: 4 | C15: 📧 Email Package | D15: PackingList_PO4901873568_Email.zip | E15: PDF + XLSX + Cover letter | F15: ~1.6 MB | G15: Ready | H15: Prepare
B16: 5 | C16: 📊 Dashboard Snapshot | D16: Dashboard_02072026.pdf | E16: Dashboard KPIs + Charts | F16: ~450 KB | G16: Ready | H16: Generate
B17: 6 | C17: 🗂 Full Archive | D17: HugoBoss_PackingSystem_Archive.zip | E17: Complete workbook + all exports | F17: ~4.8 MB | G17: Ready | H17: Archive
B19: EXPORT SETTINGS
B20: Export Folder: | D20: {=SETTINGS!C11} -> C:\HugoBoss\Exports | G20: (Change in SETTINGS)
B21: Print Area: | D21: {=SETTINGS!C10} -> A1:AZ100 | G21: A4 Landscape · Fit to page
B22: PDF Quality: | D22: High (300 DPI) | E22: Include Charts: | G22: Yes
B23: Password Protect: | D23: No | E23: Compress Images: | G23: Auto
B25: EXPORT LOG
B26: Timestamp | C26: File | D26: Format | E26: Size | F26: Duration | G26: User | H26: Status
B27: 02.07.2026 14:32:11 | C27: PackingList_PO4901873568.pdf | D27: PDF | E27: 1.2 MB | F27: 1.4s | G27: Packing Manager | H27: ✓ Success
B28: 02.07.2026 14:33:05 | C28: PackingList_PO4901873568.xlsx | D28: XLSX | E28: 380 KB | F28: 0.8s | G28: Packing Manager | H28: ✓ Success
B29: 02.07.2026 14:35:22 | C29: Dashboard_02072026.pdf | D29: PDF | E29: 450 KB | F29: 1.1s | G29: Packing Manager | H29: ✓ Success
B30: 02.07.2026 15:01:47 | C30: PackingList_PO4901893255.pdf | D30: PDF | E30: 720 KB | F30: 1.2s | G30: Packing Manager | H30: ✓ Success
B32: QUICK ACCESS — Related Sheets
B33: Sheet | D33: Purpose | F33: Ready to Export | H33: Rows
B34: PACKING_LIST | D34: Main working sheet | F34: ✓ Yes | H34: 30
B35: DASHBOARD | D35: KPIs & Charts | F35: ✓ Yes | H35: 65
B36: CUT_SHEET | D36: Production comparison | F36: ✓ Yes | H36: 81
B37: CARTON_ALLOCATION | D37: Allocation report | F37: ✓ Yes | H37: 53
B38: PO_MASTER | D38: Full PO database | F38: ✓ Yes | H38: 75
B40: ⚠ Export operations require macros enabled. Filename convention: PackingList_POxxxx.[format] • All exports are logged.
